Workbook

Sheet 速览对比
A1: 型号 | B1: 架构代际 | C1: GPU 芯片 | D1: 分类 | E1: CUDA 核心 | F1: Tensor 核心 | G1: FP32 | H1: FP16 非Tensor | I1: FP16 Tensor 稠密 | J1: FP16 Tensor 稀疏 | K1: TF32 Tensor 稠密 | L1: TF32 Tensor 稀疏 | M1: FP64 非Tensor | N1: FP64 Tensor | O1: INT8 峰值 | P1: INT4/FP8/FP4 峰值 | Q1: 低精度类型 | R1: 显存 (GB) | S1: 带宽 (GB/s) | T1: TDP (W) | U1: Target Markets / 目标市场 | V1: 目标市场（细分 2） | W1: 目标市场（细分 3） | X1: GPU / 图形处理单元（架构） | Y1: GPU Cores / CUDA 单元数 | Z1: Tensor Cores / Tensor 核数 | AA1: Core Clock / 基本频率 | AB1: Boost Clock(s) / 超频频率 | AC1: Memory Clock / 显存频率 | AD1: Memory Bus Width / 显存位宽 | AE1: Memory Bandwidth / 显存带宽 | AF1: VRAM / 显存 | AG1: FP16 Computing (non-Tensor) / 半精性能 non-Tensor | AH1: FP16 Tensor Computing/ 半精 Tensor性能 | AI1: FP32 Computing (non-Tensor) / 单精性能 non-Tensor | AJ1: TF32 Tensor Computing / TF32 Tensor性能 | AK1: FP64 Computing (non-Tensor) / 双精性能 non-Tensor | AL1: FP64 Tensor Computing / FP64 Tensor性能 | AM1: INT8 Computing / INT8 性能 | AN1: INT4 Computing / INT4 性能 | AO1: Interconnect Bandwidth / GPU-GPU带宽 | AP1: Transistor Count / 晶体管数量 | AQ1: Form Factor / 外形 | AR1: TDP / 设计功耗
A2: GB300 NVL72 | B2: Blackwell Ultra | C2: GB300（Blackwell Ultra） | D2: 数据中心 | E2: 16896 | F2: 528 | G2: 83 | H2: 166 | I2: 2500 | J2: 5000 | K2: 1250 | L2: 2500 | M2: 1.4 | N2: 1.4 | O2: 375 | P2: 20000 | Q2: FP4 | R2: 288 | S2: 8000 | T2: 1400 | U2: 数据中心（AI 工厂 / 机柜级方案） | X2: GB300（Blackwell Ultra） | Y2: 16896（每GPU） | Z2: 528（每GPU） | AA2: - | AB2: - | AC2: HBM3e | AD2: 8192-bit | AE2: 8 TB/s | AF2: 288 GB HBM3e（每GPU） | AG2: ≈166 TFLOPS | AH2: ≈2,500 | ≈5,000 TFLOPS² | AI2: ≈83 TFLOPS | AJ2: ≈1,250 | ≈2,500 TFLOPS² | AK2: ≈1.4 TFLOPS | AL2: ≈1.4 TFLOPS | AM2: ≈187 | ≈375 TOPS² | AN2: FP4：≈15 | ≈20 PFLOPS² | AO2: NVLink 5: 1.8 TB/s（每GPU） NVLink-C2C: 900 GB/s（GPU↔Grace CPU） | AP2: 4NP 2080亿（GPU） | AQ2: GB300 超级芯片（1×Grace+2×B300）/ NVL72 整柜全液冷 | AR2: ≈1,400W（GPU）；整柜≈135kW
A3: B300 SXM | B3: Blackwell Ultra | C3: GB300（Blackwell Ultra） | D3: 数据中心 | E3: 16896 | F3: 528 | G3: 75 | H3: 150 | I3: 2250 | J3: 4500 | K3: 1125 | L3: 2250 | M3: 1.25 | N3: 1.25 | O3: 375 | P3: 18000 | Q3: FP4 | R3: 288 | S3: 8000 | T3: 1400 | U3: 2025年3月GTC发布的Blackwell Ultra架构GPU（GB100双芯粒，TSMC 4NP，2080亿晶体管）：288GB HBM3e显存、8TB/s带宽，FP4稠密算力较B200提升50%，attention吞吐约2倍。面向万亿参数大模型训练、长上下文推理与AI工厂（HGX B300 / DGX B300 / GB300 NVL72），需液冷 | X3: GB300（Blackwell Ultra） | Y3: 16896 | Z3: 528 | AA3: - | AB3: - | AC3: HBM3e | AD3: 8192-bit | AE3: 8 TB/s | AF3: 288 GB HBM3e | AG3: ≈150 TFLOPS | AH3: 2,250 | 4,500 TFLOPS² | AI3: 75 TFLOPS | AJ3: 1,125 | 2,250 TFLOPS² | AK3: ≈1.25 TFLOPS | AL3: ≈1.25 TFLOPS | AM3: ≈187 | ≈375 TOPS² | AN3: FP4：13.5 | 18 PFLOPS² | AO3: NVLink 5: 1.8 TB/s PCIe Gen6: 256 GB/s | AP3: 4NP 2080亿 | AQ3: SXM6 接口，适用于NVLink专用主板（需液冷） | AR3: 1400W
A4: B200 SXM | B4: Blackwell | C4: GB100（Blackwell，双芯粒） | D4: 数据中心 | E4: 16896 | F4: 528 | G4: 75 | H4: 150 | I4: 2250 | J4: 4500 | K4: 1125 | L4: 2250 | M4: 37 | N4: 37 | O4: 9000 | P4: 18000 | Q4: FP4 | R4: 192 | S4: 8000 | T4: 1000 | U4: 这是一款采用台积电4NP工艺的GPU，采用NVIDIA Blackwell架构，上市时间为2024年。具有2080亿个晶体管、16896个CUDA核心和192GB HBM3e显存，FP32算力75 TFLOPS，总功耗为1000W。 | X4: GB100（Blackwell，双芯粒） | Y4: 16896 | Z4: 528 | AA4: 1665 MHz | AB4: 1837 MHz | AC4: 2000 MHz | AD4: 2*4096bit | AE4: 8 TB/s | AF4: 2*96GB HBM3e=192GB | AG4: ≈150 TFLOPS | AH4: 2,250 | 4,500 TFLOPS² | AI4: 75 TFLOPS | AJ4: 1,125 | 2,250 TFLOPS² | AK4: 37 TFLOPS | AL4: 37 TFLOPS | AM4: 4,500 | 9,000 TOPS² | AN4: FP4：9 | 18 PFLOPS² | AO4: PCIe Gen6 :256 GB/s NVLink: 1800GB/s | AP4: 4NP 2080亿 | AQ4: SXM 接口，适合于NVLink专用主板 | AR4: 1000W
A5: RTX PRO 6000 Blackwell | B5: Blackwell | C5: GB202（Blackwell） | D5: 专业工作站 | E5: 24064 | F5: 752 | G5: 125 | H5: 125 | I5: 500 | J5: 1000 | K5: 250 | L5: 500 | M5: 1.95 | O5: 2000 | P5: 4000 | Q5: FP4 | R5: 96 | S5: 1792 | T5: 600 | U5: 2025年3月发布的Blackwell旗舰专业卡（工作站版）：96GB GDDR7 ECC超大显存，第5代Tensor Core支持FP4，支持MIG（4×24GB）。面向本地AI开发、大模型微调与推理、3D渲染、仿真、视频制作（另有Max-Q 300W版与被动散热服务器版） | X5: GB202（Blackwell） | Y5: 24064 | Z5: 752 | AA5: - | AB5: ≈2617 MHz | AC5: 28Gbps GDDR7 | AD5: 512-bit | AE5: 1,792 GB/s | AF5: 96 GB GDDR7 w/ ECC | AG5: 125 TFLOPS | AH5: 500 | 1,000 TFLOPS² | AI5: 125 TFLOPS | AJ5: 250 | 500 TFLOPS² | AK5: ≈1.95 TFLOPS | AL5: - | AM5: 1,000 | 2,000 TOPS² | AN5: FP4：2 | 4 PFLOPS² | AO5: PCIe 5.0 x16：128 GB/s（无NVLink） | AP5: 4NP 922亿 | AQ5: PCIe 5.0 x16 双槽位 主动散热（双流通式） | AR5: 600W
A6: RTX PRO 6000D Blackwell | B6: Blackwell | C6: GB202（Blackwell） | D6: 专业工作站 | E6: 19968 | F6: 624 | G6: 97 | H6: 97 | I6: 388 | J6: 776 | K6: 194 | L6: 388 | M6: 1.5 | O6: 1552 | P6: 3100 | Q6: FP4 | R6: 84 | S6: 1398 | T6: 600 | U6: RTX PRO 6000的中国合规版（2025年Q3，面向中国大陆及港澳）：CUDA核心削减约17%，84GB GDDR7，带宽降至1398 GB/s，无NVLink、无MIG。定位AI推理、中小模型微调、3D渲染、工业仿真（双槽被动散热服务器形态） | X6: GB202（Blackwell） | Y6: 19968 | Z6: 624 | AA6: - | AB6: ≈2430 MHz | AC6: ≈25Gbps GDDR7 | AD6: 448-bit | AE6: 1,398 GB/s | AF6: 84 GB GDDR7 w/ ECC | AG6: ≈97 TFLOPS | AH6: ≈388 | ≈776 TFLOPS² | AI6: ≈97 TFLOPS | AJ6: ≈194 | ≈388 TFLOPS² | AK6: ≈1.5 TFLOPS | AL6: - | AM6: ≈776 | ≈1,552 TOPS² | AN6: FP4：≈1.6 | ≈3.1 PFLOPS² | AO6: PCIe 5.0 x16：128 GB/s（无NVLink） | AP6: 4NP 922亿 | AQ6: PCIe 5.0 x16 双槽位 被动散热 | AR6: 600W
A7: RTX PRO 5000 Blackwell | B7: Blackwell | C7: GB202（Blackwell） | D7: 专业工作站 | E7: 14080 | F7: 440 | G7: 65 | H7: 65 | I7: 260 | J7: 520 | K7: 130 | L7: 260 | M7: 1 | O7: 1040 | P7: 2100 | Q7: FP4 | R7: 48 | S7: 1344 | T7: 300 | U7: 2025年发布的Blackwell高端专业卡：48GB（可选72GB）GDDR7 ECC，支持MIG（2实例）。面向AI开发、LLM推理、仿真、3D渲染与视频制作 | X7: GB202（Blackwell） | Y7: 14080 | Z7: 440 | AA7: - | AB7: ≈2310 MHz | AC7: 28Gbps GDDR7 | AD7: 384-bit | AE7: 1,344 GB/s | AF7: 48 GB（可选72 GB）GDDR7 w/ ECC | AG7: 65 TFLOPS | AH7: 260 | 520 TFLOPS² | AI7: 65 TFLOPS | AJ7: 130 | 260 TFLOPS² | AK7: ≈1.0 TFLOPS | AL7: - | AM7: 520 | 1,040 TOPS² | AN7: FP4：1 | 2.1 PFLOPS² | AO7: PCIe 5.0 x16：128 GB/s（无NVLink） | AP7: 4NP 922亿 | AQ7: PCIe 5.0 x16 双槽位 主动散热 | AR7: 300W
A8: RTX PRO 4500 Blackwell | B8: Blackwell | C8: GB203（Blackwell） | D8: 专业工作站 | E8: 10496 | F8: 328 | G8: 51 | H8: 51 | I8: 204 | J8: 408 | K8: 102 | L8: 204 | M8: 0.8 | O8: 816 | P8: 1600 | Q8: FP4 | R8: 32 | S8: 896 | T8: 200 | U8: Blackwell主流专业卡（2025年，工作站版）：32GB GDDR7 ECC。面向生成式AI、3D渲染、数据可视化与仿真（另有165W被动散热服务器版，带宽800 GB/s） | X8: GB203（Blackwell） | Y8: 10496 | Z8: 328 | AA8: - | AB8: ≈2430 MHz | AC8: 28Gbps GDDR7 | AD8: 256-bit | AE8: 896 GB/s | AF8: 32 GB GDDR7 w/ ECC | AG8: 51 TFLOPS | AH8: 204 | 408 TFLOPS² | AI8: 51 TFLOPS | AJ8: 102 | 204 TFLOPS² | AK8: ≈0.8 TFLOPS | AL8: - | AM8: 408 | 816 TOPS² | AN8: FP4：0.8 | 1.6 PFLOPS² | AO8: PCIe 5.0 x16：128 GB/s（无NVLink） | AP8: 4NP 456亿 | AQ8: PCIe 5.0 x16 双槽位 主动散热 | AR8: 200W
A9: RTX PRO 4000 Blackwell | B9: Blackwell | C9: GB203（Blackwell） | D9: 专业工作站 | E9: 8960 | F9: 280 | G9: 40 | H9: 40 | I9: 160 | J9: 320 | K9: 80 | L9: 160 | M9: 0.63 | O9: 640 | P9: 1290 | Q9: FP4 | R9: 24 | S9: 672 | T9: 145 | U9: Blackwell入门级专业卡（2025年）：单槽145W，24GB GDDR7 ECC。面向AI原型开发、CAD/CAM、3D渲染与边缘/高密度部署（另有70W SFF半高版，带宽432 GB/s） | X9: GB203（Blackwell） | Y9: 8960 | Z9: 280 | AA9: - | AB9: ≈2230 MHz | AC9: 28Gbps GDDR7 | AD9: 192-bit | AE9: 672 GB/s | AF9: 24 GB GDDR7 w/ ECC | AG9: 40 TFLOPS | AH9: 160 | 320 TFLOPS² | AI9: 40 TFLOPS | AJ9: 80 | 160 TFLOPS² | AK9: ≈0.63 TFLOPS | AL9: - | AM9: 320 | 640 TOPS² | AN9: FP4：0.64 | 1.29 PFLOPS² | AO9: PCIe 5.0 x16：128 GB/s（无NVLink） | AP9: 4NP 456亿 | AQ9: PCIe 5.0 x16 单槽位 主动散热 | AR9: 145W
A10: RTX 5090 | B10: Blackwell | C10: GB202（Blackwell） | D10: 消费级 | E10: 21760 | F10: 680 | G10: 104.8 | H10: 104.8 | I10: 419 | J10: 838 | K10: 209 | L10: 419 | M10: 1.64 | O10: 1676 | P10: 3350 | Q10: FP4 | R10: 32 | S10: 1792 | T10: 575 | U10: 深度学习、RTX (实时光线追踪) | X10: GB202（Blackwell） | Y10: 21760 | Z10: 680 | AA10: 2017 MHz | AB10: 2407 MHz | AC10: 28Gbps GDDR7 | AD10: 512-bit | AE10: 1,792 GB/s | AF10: 32GB GDDR7 | AG10: 104.8 TFLOPS | AH10: 419 | 838 TFLOPS² | AI10: 104.8 TFLOPS | AJ10: 209 | 419 TFLOPS² | AK10: 1.64 TFLOPS | AL10: - | AM10: 838 | 1,676 TOPS² | AN10: FP4：1.68 | 3.35 PFLOPS² | AO10: PCIe 5.0 x16：128 GB/s（无NVLink） | AP10: 4NP 922亿 | AQ10: PCIe 5.0 x16 双槽 主动散热（FE双流通式） | AR10: 575W
A11: RTX 5090D | B11: Blackwell | C11: GB202（Blackwell） | D11: 消费级 | E11: 21760 | F11: 680 | G11: 104.8 | H11: 104.8 | I11: 297 | J11: 595 | K11: 148 | L11: 297 | M11: 1.64 | O11: 1190 | P11: 2380 | Q11: FP4 | R11: 32 | S11: 1792 | T11: 575 | U11: 深度学习、RTX (实时光线追踪) | X11: GB202（Blackwell） | Y11: 21760 | Z11: 680 | AA11: 2017 MHz | AB11: 2407 MHz | AC11: 28Gbps GDDR7 | AD11: 512-bit | AE11: 1,792 GB/s | AF11: 32GB GDDR7 | AG11: 104.8 TFLOPS | AH11: ≈297 | ≈595 TFLOPS² | AI11: 104.8 TFLOPS | AJ11: ≈148 | ≈297 TFLOPS² | AK11: 1.64 TFLOPS | AL11: - | AM11: ≈595 | ≈1,190 TOPS² | AN11: FP4：≈1.19 | ≈2.38 PFLOPS² | AO11: PCIe 5.0 x16：128 GB/s（无NVLink） | AP11: 4NP 922亿 | AQ11: PCIe 5.0 x16 双槽 主动散热（FE双流通式） | AR11: 575W
A12: RTX 5080 | B12: Blackwell | C12: GB203（Blackwell） | D12: 消费级 | E12: 10752 | F12: 336 | G12: 56.3 | H12: 56.3 | I12: 225.4 | J12: 450.7 | K12: 112.7 | L12: 225.4 | M12: 0.88 | O12: 901.4 | P12: 1800 | Q12: FP4 | R12: 16 | S12: 960 | T12: 360 | U12: 消费级（高端游戏 / 本地 AI 推理） | X12: GB203（Blackwell） | Y12: 10752 | Z12: 336 | AA12: 2.30 GHz | AB12: 2.62 GHz | AC12: 30 Gbps GDDR7 | AD12: 256-bit | AE12: 960 GB/s | AF12: 16GB GDDR7 | AG12: 56.3 TFLOPS | AH12: 225.4 | 450.7 TFLOPS² | AI12: 56.3 TFLOPS | AJ12: 112.7 | 225.4 TFLOPS² | AK12: 0.88 TFLOPS | AL12: - | AM12: 450.7 | 901.4 TOPS² | AN12: FP4：0.9 | 1.8 PFLOPS² | AO12: PCIe Gen5 x16 | AP12: 4NP 456亿（GB203） | AQ12: PCIe 双槽（公版 FE） | AR12: 360W
A13: RTX 5070 Ti | B13: Blackwell | C13: GB203（Blackwell） | D13: 消费级 | E13: 8960 | F13: 280 | G13: 43.9 | H13: 43.9 | I13: 175.6 | J13: 351.3 | K13: 87.8 | L13: 175.6 | M13: 0.69 | O13: 702.6 | P13: 1400 | Q13: FP4 | R13: 16 | S13: 896 | T13: 300 | U13: 消费级（高端游戏 / 本地 AI 推理） | X13: GB203（Blackwell） | Y13: 8960 | Z13: 280 | AA13: 2.30 GHz | AB13: 2.45 GHz | AC13: 28 Gbps GDDR7 | AD13: 256-bit | AE13: 896 GB/s | AF13: 16GB GDDR7 | AG13: 43.9 TFLOPS | AH13: 175.6 | 351.3 TFLOPS² | AI13: 43.9 TFLOPS | AJ13: 87.8 | 175.6 TFLOPS² | AK13: 0.69 TFLOPS | AL13: - | AM13: 351.3 | 702.6 TOPS² | AN13: FP4：0.7 | 1.4 PFLOPS² | AO13: PCIe Gen5 x16 | AP13: 4NP 456亿（GB203） | AQ13: PCIe 双槽（AIC 非公版） | AR13: 300W
A14: H200 SXM | B14: Hopper | C14: GH100（Hopper） | D14: 数据中心 | E14: 16896 | F14: 528 | G14: 67 | H14: 267.6 | I14: 989 | J14: 1979 | K14: 494 | L14: 989 | M14: 34 | N14: 67 | O14: 3958 | P14: 3958 | Q14: FP8 | R14: 141 | S14: 4800 | T14: 700 | U14: 这是一款采用了台积电 4nm工艺的GPU，采用Nvidia Hopper架构，上市时间为2023年11月。具有 800亿个晶体管、16896 个 CUDA 核心和 141GB HBM3e 显存，具备 50MB 二级缓存，理论算力67TFLOPS，总功耗为700W。 | X14: GH100（Hopper） | Y14: 16896 | Z14: 528 | AA14: 1590 MHz | AB14: 1980 MHz | AC14: 1313 MHz | AD14: 6144-bit | AE14: 4800GB/s | AF14: 141GB HBM3e | AG14: 267.6 TFLOPS | AH14: 989 | 1,979 TFLOPS² | AI14: 67 TFLOPS | AJ14: 494 | 989 TFLOPS² | AK14: 34 TFLOPS | AL14: 67 TFLOPS | AM14: 1,979 | 3,958 TOPS² | AN14: FP8：1,979 | 3,958 TFLOPS² | AO14: PCIe Gen5:128 GB/s NVLink: 900GB/s | AP14: 4 nm 800亿 | AQ14: SXM 接口，适合于NVLink专用主板 | AR14: 700W
A15: H200 PCIe（NVL） | B15: Hopper | C15: GH100（Hopper） | D15: 数据中心 | E15: 16896 | F15: 528 | G15: 60 | H15: 240 | I15: 835 | J15: 1671 | K15: 418 | L15: 835 | M15: 30 | N15: 60 | O15: 3341 | P15: 3341 | Q15: FP8 | R15: 141 | S15: 4800 | T15: 600 | U15: H200 的 PCIe 形态（官方型号 H200 NVL，2024年11月上市）：141GB HBM3e 与 4.8TB/s 带宽同 SXM 版一致，算力较 SXM 低约 15%（FP16 稠密 835 TFLOPS），600W 可配置、双槽风冷，支持 2/4 卡 NVLink 桥（900GB/s）。面向标准 PCIe 服务器的 AI 推理与训练部署 | X15: GH100（Hopper） | Y15: 16896 | Z15: 528 | AA15: - | AB15: - | AC15: HBM3e | AD15: 6144-bit | AE15: 4.8 TB/s | AF15: 141 GB HBM3e | AG15: 240 TFLOPS | AH15: 835 | 1,671 TFLOPS² | AI15: 60 TFLOPS | AJ15: 418 | 835 TFLOPS² | AK15: 30 TFLOPS | AL15: 60 TFLOPS | AM15: 1,671 | 3,341 TOPS² | AN15: FP8：1,671 | 3,341 TFLOPS² | AO15: PCIe Gen5 x16: 128 GB/s NVLink 桥（2/4卡）: 900 GB/s | AP15: 4nm 800亿 | AQ15: PCIe 5.0 x16 双槽 被动散热（风冷） | AR15: 600W（可配置）
A16: H100 SXM | B16: Hopper | C16: GH100（Hopper） | D16: 数据中心 | E16: 16896 | F16: 528 | G16: 67 | H16: 267.6 | I16: 989 | J16: 1979 | K16: 494 | L16: 989 | M16: 34 | N16: 67 | O16: 3958 | P16: 3958 | Q16: FP8 | R16: 80 | S16: 3350 | T16: 700 | U16: H100 是全球范围内最大的性能出众的加速器，拥有革命性的 Transformer 引擎和高度可扩展的 NVIDIA NVLink® 互连技术等突破性功能，可推动庞大的 AI 语言模型、深度推荐系统、基因组学和复杂数字孪生的发展 | X16: GH100（Hopper） | Y16: 16896 | Z16: 528 | AA16: 1590 MHz | AB16: 1980 MHz | AC16: 2.6 GHz HBM3 | AD16: 5120 bit | AE16: 3.35TB/s | AF16: 80GB | AG16: 267.6 TFLOPS | AH16: 989 | 1,979 TFLOPS² | AI16: 67 TFLOPS | AJ16: 494 | 989 TFLOPS² | AK16: 34 TFLOPS | AL16: 67 TFLOPS | AM16: 1,979 | 3,958 TOPS² | AN16: FP8：1,979 | 3,958 TFLOPS² | AO16: NVLink ：900GB/s | AP16: 4 nm 80,000 million | AQ16: SXM 接口，适合于NVLink专用主板 | AR16: 700W
A17: H800 SXM | B17: Hopper | C17: GH100（Hopper） | D17: 数据中心 | E17: 16896 | F17: 528 | G17: 67 | H17: 267.6 | I17: 989 | J17: 1979 | K17: 494 | L17: 989 | M17: 34 | N17: 67 | O17: 3958 | P17: 3958 | Q17: FP8 | R17: 80 | S17: 3350 | T17: 700 | U17: 基于 GH800 图形处理器,SXM5接口，有助于提高机器学习应用程序的速度，第四代tensor core， 支持FPB 和transformer 引擎 | X17: GH100（Hopper） | Y17: 16896 | Z17: 528 | AA17: 1590 MHz | AB17: 1980 MHz | AC17: 2.6 GHz HBM3 | AD17: 5120 bit | AE17: 3.35TB/s | AF17: 80 GB | AG17: 267.6 TFLOPS | AH17: 989 | 1,979 TFLOPS² | AI17: 67 TFLOPS | AJ17: 494 | 989 TFLOPS² | AK17: 34 TFLOPS | AL17: 67 TFLOPS | AM17: 1,979 | 3,958 TOPS² | AN17: FP8：1,979 | 3,958 TFLOPS² | AO17: NVLink™: 400GB/s PCIe 5.0: 128GB/s | AP17: 4 nm 80,000 million | AQ17: SXM 接口，适合于NVLink专用主板 | AR17: 700W
A18: H100 PCIe | B18: Hopper | C18: GH100（Hopper） | D18: 数据中心 | E18: 14592 | F18: 456 | G18: 51 | H18: 204 | I18: 756 | J18: 1513 | K18: 378 | L18: 756 | M18: 26 | N18: 51 | O18: 3026 | P18: 3026 | Q18: FP8 | R18: 80 | S18: 2000 | T18: 350 | U18: H100 是全球范围内最大的性能出众的加速器，拥有革命性的 Transformer 引擎和高度可扩展的 NVIDIA NVLink® 互连技术等突破性功能，可推动庞大的 AI 语言模型、深度推荐系统、基因组学和复杂数字孪生的发展 | X18: GH100（Hopper） | Y18: 14592 | Z18: 456 | AA18: 1095 MHz | AB18: 1755 MHz | AC18: 3.2 GHz HBM2e | AD18: 5120 bit | AE18: 2TB/s | AF18: 80GB | AG18: 204.9 TFLOPS | AH18: 756 | 1,513 TFLOPS² | AI18: 51 TFLOPS | AJ18: 378 | 756 TFLOPS² | AK18: 26 TFLOPS | AL18: 51 TFLOPS | AM18: 1,513 | 3,026 TOPS² | AN18: FP8：1,513 | 3,026 TFLOPS² | AO18: NVLink ： 600GB/s PCIe 5.0 ：128GB/ | AP18: 4 nm 80,000 million | AQ18: PCIe5.0 双槽位 被动散热 | AR18: 350W
A19: H800 PCIe | B19: Hopper | C19: GH100（Hopper） | D19: 数据中心 | E19: 14592 | F19: 456 | G19: 51 | H19: 204 | I19: 756 | J19: 1513 | K19: 378 | L19: 756 | M19: 26 | N19: 51 | O19: 3026 | P19: 3026 | Q19: FP8 | R19: 80 | S19: 2000 | T19: 350 | U19: 基于 GH800 图形处理器,SXM5接口，有助于提高机器学习应用程序的速度，第四代tensor core， 支持FPB 和transformer 引擎 | X19: GH100（Hopper） | Y19: 14592 | Z19: 456 | AA19: 1095 MHz | AB19: 1755 MHz | AC19: 3.2 GHz HBM2e | AD19: 5120 bit | AE19: 2TB/s | AF19: 80 GB | AG19: 204.9 TFLOPS | AH19: 756 | 1,513 TFLOPS² | AI19: 51 TFLOPS | AJ19: 378 | 756 TFLOPS² | AK19: 26 TFLOPS | AL19: 51 TFLOPS | AM19: 1,513 | 3,026 TOPS² | AN19: FP8：1,513 | 3,026 TFLOPS² | AO19: NVLink™: 400GB/s PCIe 5.0: 128GB/s | AP19: 4 nm 80,000 million | AQ19: PCIe5.0 x16 双插槽风冷式 | AR19: 300-350W
A20: H20 SXM 96GB | B20: Hopper | C20: GH100（Hopper） | D20: 数据中心 | E20: 9984 | F20: 312 | G20: 44 | H20: 176 | I20: 148 | J20: 296 | K20: 74 | L20: 148 | M20: 1 | N20: 1 | O20: 592 | P20: 592 | Q20: FP8 | R20: 96 | S20: 4000 | T20: 400 | U20: 2023年11月发布的中国特供AI加速卡（HGX 8卡形态）：Hopper架构GH100，96GB HBM3、4TB/s带宽、NVLink 900GB/s保留，算力大幅削减（FP16 Tensor 148 TFLOPS）。面向垂类模型训练与大模型推理 | X20: GH100（Hopper） | Y20: 9984 | Z20: 312 | AA20: - | AB20: - | AC20: HBM3 | AD20: 6144-bit | AE20: 4 TB/s | AF20: 96 GB HBM3 | AG20: 176 TFLOPS | AH20: 148 | 296 TFLOPS² | AI20: 44 TFLOPS | AJ20: 74 | 148 TFLOPS² | AK20: 1 TFLOPS | AL20: 1 TFLOPS | AM20: 296 | 592 TOPS² | AN20: FP8：296 | 592 TFLOPS² | AO20: PCIe Gen5 x16:128 GB/s NVLink: 900GB/s | AP20: 4nm 800亿 | AQ20: SXM 接口，适合于NVLink专用主板 | AR20: 400W
A21: L40S | B21: Ada Lovelace | C21: AD102（Ada Lovelace） | D21: 数据中心 | E21: 18176 | F21: 568 | G21: 91.61 | H21: 91.6 | I21: 362.05 | J21: 733 | K21: 183 | L21: 366 | M21: 1.4 | O21: 1466 | P21: 1466 | Q21: FP8 | R21: 48 | S21: 864 | T21: 350 | U21: 基于 AD102 图形处理器,PCI-E4.0接口，18176 个着色单元,有助于提高机器学习应用程序的速度，第四代tensor core， 支持FPB 和transformer 引擎，第三代 RT Core | X21: AD102（Ada Lovelace） | Y21: 18176 | Z21: 568 | AA21: 1110 MHz | AB21: 2520 MHz | AC21: 18 GHz GDDR6 | AD21: 384 bit | AE21: 864GB/ s | AF21: 48 GB | AG21: 91.6 TFLOPS | AH21: 362 | 733 TFLOPS² | AI21: 91.61 TFLOPS | AJ21: 183 | 366 TFLOPS² | AK21: 1.4 TFLOPS | AL21: - | AM21: 733 | 1,466 TOPS² | AN21: FP8：733 | 1,466 TFLOPS² | AO21: PCIe 4.0 x16：双向 64 GB/s | AP21: 4N 76,300 million | AQ21: PCIe 4.0 x16 双槽位 被动散热 | AR21: 350W
A22: L40 | B22: Ada Lovelace | C22: AD102（Ada Lovelace） | D22: 数据中心 | E22: 18176 | F22: 568 | G22: 90.52 | H22: 90.5 | I22: 181 | J22: 362 | K22: 90.5 | L22: 181 | M22: 1.4 | O22: 724 | P22: 724 | Q22: FP8 | R22: 48 | S22: 864 | T22: 300 | U22: 基于 AD102 图形处理器,PCI-E4.0接口，18176 个着色单元,有助于提高机器学习应用程序的速度，第三代 RT Core | X22: AD102（Ada Lovelace） | Y22: 18176 | Z22: 568 | AA22: 735 MHz | AB22: 2490 MHz | AC22: 18 GHz GDDR6 | AD22: 384 bit | AE22: 864.0 GB/s | AF22: 48GB | AG22: 90.5 TFLOPS | AH22: 181 | 362 TFLOPS² | AI22: 90.52 TFLOPS | AJ22: 90.5 | 181 TFLOPS² | AK22: 1.4 TFLOPS | AL22: - | AM22: 362 | 724 TOPS² | AN22: FP8：362 | 724 TFLOPS² | AO22: PCIe 4.0 x16：双向 64 GB/s | AP22: 4N 76,300 million | AQ22: PCIe 4.0 x16 双槽位 被动散热 | AR22: 300W
A23: L20 PCIe | B23: Ada Lovelace | C23: AD102（Ada Lovelace） | D23: 数据中心 | E23: 11776 | F23: 368 | G23: 59.8 | H23: 59.8 | I23: 119.5 | J23: 239 | K23: 59.8 | L23: 119.5 | M23: 0.93 | O23: 478 | P23: 478 | Q23: FP8 | R23: 48 | S23: 864 | T23: 275 | U23: 这是一款采用了台积电4N工艺的GPU，采用Nvidia Ada Lovelace架构，上市时间为2023年11月。具有 763亿个晶体管、11776 个 CUDA 核心和 48GB GDDR6 显存，具备 96MB 二级缓存，理论算力59.35TFLOPS，总功耗为275W。 | X23: AD102（Ada Lovelace） | Y23: 11776 | Z23: 368 | AA23: 1440 MHz | AB23: 2520 MHz | AC23: 2250 MHz | AD23: 384bit | AE23: 864 GB/s | AF23: 48 GB GDDR6 W/ ECC | AG23: 59.8 TFLOPS | AH23: 119.5 | 239 TFLOPS² | AI23: 59.8 TFLOPS | AJ23: 59.8 | 119.5 TFLOPS² | AK23: 0.93 TFLOPS | AL23: - | AM23: 239 | 478 TOPS² | AN23: FP8：239 | 478 TFLOPS² | AO23: PCIe Gen4 x16：64 GB/s | AP23: 4N 763亿 | AQ23: PCIe4.0 x16 双插槽风冷式 | AR23: 275W
A24: L2 PCIe | B24: Ada Lovelace | C24: AD106（Ada Lovelace） | D24: 数据中心 | E24: 4608 | F24: 144 | G24: 24.1 | H24: 24.1 | I24: 48.3 | J24: 96.5 | K24: 24.1 | L24: 48.3 | M24: 0.38 | O24: 193 | P24: 193 | Q24: FP8 | R24: 24 | S24: 300 | T24: 70 | X24: AD106（Ada Lovelace） | AE24: 300 GB/s | AF24: 24 GB GDDR6 W/ ECC | AG24: 24.1 TFLOPS | AH24: 48.3 | 96.5 TFLOPS² | AI24: 24.1 TFLOPS | AJ24: 24.1 | 48.3 TFLOPS* | AK24: ≈0.38 TFLOPS | AM24: 96.5 | 193 TOPS² | AN24: FP8：96.5 | 193 TFLOPS² | AO24: PCIe Gen4 x16：64 GB/s | AP24: 4N 358亿（AD104） | AQ24: PCIe 4.0 x16 单槽半高（LP）被动散热 | AR24: ≈70W
A25: RTX4090 | B25: Ada Lovelace | C25: AD102（Ada Lovelace） | D25: 消费级 | E25: 16384 | F25: 512 | G25: 82.6 | H25: 82.6 | I25: 330.3 | J25: 660.6 | K25: 165.2 | L25: 330.3 | M25: 1.29 | O25: 1321 | P25: 1321 | Q25: FP8 | R25: 24 | S25: 1008 | T25: 450 | U25: 深度学习 | V25: RTX (实时光线追踪) | W25: VR | X25: AD102（Ada Lovelace） | Y25: 16384 | Z25: 512 | AA25: 2235 MHz | AB25: 2520 MHz | AC25: 21Gbps GDDR6X | AD25: 384-bit | AE25: 1008 GB/sec | AF25: 24GB | AG25: 82.6 TFLOPS | AH25: 330.3 | 660.6 TFLOPS² | AI25: 82.6 TFLOPS | AJ25: 165.2 | 330.3 TFLOPS² | AK25: 1.29 TFLOPS | AL25: - | AM25: 660.6 | 1,321 TOPS² | AN25: FP8：660.6 | 1,321 TFLOPS² | AO25: 300 GB/s | AP25: TSMC 4N 76.3B | AQ25: PCIe4.0 三槽位 正反双风扇 主动散热 | AR25: 450W
A26: A800 SXM 80GB | B26: Ampere | C26: GA100 (Ampere) | D26: 数据中心 | E26: 6912 | F26: 432 | G26: 19.5 | H26: 78 | I26: 312 | J26: 624 | K26: 156 | L26: 312 | M26: 9.7 | N26: 19.5 | O26: 1248 | P26: 2496 | Q26: INT4 | R26: 80 | S26: 2039 | T26: 400 | U26: 新引入FP64, TF32, BF16 Tensor Core, 支持MIG, 深度学习/HPC大规模算例并行加速计算 | X26: GA100 (Ampere) | Y26: 6912 | Z26: 432 | AA26: 1155 MHz | AB26: 1410 MHz | AC26: 3.2GHz HBM2 | AD26: 5120-bit | AE26: 2,039 GB/s | AF26: 80 GB | AG26: 78 TFLOPS | AH26: 312 | 624 TFLOPS² | AI26: 19.49 TFLOPS | AJ26: 156 | 312 TFLOPS² | AK26: 9.7 TFLOPS | AL26: 19.5 TFLOPS | AM26: 624 | 1,248 TOPS² | AN26: 1,248 | 2,496 TOPS² | AO26: 400GB/sec (NVLink 3.0 2-way) | AP26: 7nm N7, 54.2B | AQ26: SXM 接口，适合于NVLink专用主板 | AR26: 400W
A27: A800 PCIe 80GB | B27: Ampere | C27: GA100 (Ampere) | D27: 数据中心 | E27: 6912 | F27: 432 | G27: 19.5 | H27: 78 | I27: 312 | J27: 624 | K27: 156 | L27: 312 | M27: 9.7 | N27: 19.5 | O27: 1248 | P27: 2496 | Q27: INT4 | R27: 80 | S27: 1935 | T27: 250 | U27: 新引入FP64, TF32, BF16 Tensor Core, 支持MIG, 深度学习/HPC大规模算例并行加速计算 | X27: GA100 (Ampere) | Y27: 6912 | Z27: 432 | AA27: 1065MHZ | AB27: 1410MHz | AC27: 3.0GHz HBM2 | AD27: 5120-bit | AE27: 1,935 GB/s | AF27: 80GB | AG27: 78 TFLOPS | AH27: 312 | 624 TFLOPS² | AI27: 19.49 TFLOPS | AJ27: 156 | 312 TFLOPS² | AK27: 9.7 TFLOPS | AL27: 19.5 TFLOPS | AM27: 624 | 1,248 TOPS² | AN27: 1,248 | 2,496 TOPS² | AO27: 400GB/sec (NVLink 3.0 2-way) | AP27: 7nm N7, 54.2B | AQ27: PCIe4.0 双槽位 被动散热 | AR27: 250W
A28: A100 SXM4 40GB | B28: Ampere | C28: GA100 (Ampere) | D28: 数据中心 | E28: 6912 | F28: 432 | G28: 19.5 | H28: 78 | I28: 312 | J28: 624 | K28: 156 | L28: 312 | M28: 9.7 | N28: 19.5 | O28: 1248 | P28: 2496 | Q28: INT4 | R28: 40 | S28: 1555 | T28: 400 | U28: 新引入FP64, TF32, BF16 Tensor Core, 支持MIG, 深度学习/HPC大规模算例并行加速计算 | X28: GA100 (Ampere) | Y28: 6912 | Z28: 432 | AA28: 1370MHz | AB28: 1410MHz | AC28: 2.4GHz HBM2 | AD28: 5120-bit | AE28: 1,555GB/sec | AF28: 40GB | AG28: 78 TFLOPS | AH28: 312 | 624 TFLOPS² | AI28: 19.5 TFLOPS | AJ28: 156 | 312 TFLOPS² | AK28: 9.7 TFLOPS | AL28: 19.5 TFLOPS | AM28: 624 | 1,248 TOPS² | AN28: 1,248 | 2,496 TOPS² | AO28: 600GB/sec (NVLink 3.0 2-way) | AP28: 7nm N7, 54.2B | AQ28: SXM 接口，适合于NVLink专用主板 | AR28: 400W
A29: A100 PCIe 40GB | B29: Ampere | C29: GA100 (Ampere) | D29: 数据中心 | E29: 6912 | F29: 432 | G29: 19.5 | H29: 78 | I29: 312 | J29: 624 | K29: 156 | L29: 312 | M29: 9.7 | N29: 19.5 | O29: 1248 | P29: 2496 | Q29: INT4 | R29: 40 | S29: 1555 | T29: 250 | U29: 新引入FP64, TF32, BF16 Tensor Core, 支持MIG, 深度学习/HPC大规模算例并行加速计算 | X29: GA100 (Ampere) | Y29: 6912 | Z29: 432 | AA29: 1370MHz | AB29: 1410MHz | AC29: 2.4GHz HBM2 | AD29: 5120-bit | AE29: 1,555GB/sec | AF29: 40GB | AG29: 78 TFLOPS | AH29: 312 | 624 TFLOPS² | AI29: 19.5 TFLOPS | AJ29: 156 | 312 TFLOPS² | AK29: 9.7 TFLOPS | AL29: 19.5 TFLOPS | AM29: 624 | 1,248 TOPS² | AN29: 1,248 | 2,496 TOPS² | AO29: 600GB/sec (NVLink 3.0 2-way) | AP29: 7nm N7, 54.2B | AQ29: PCIe4.0 双槽位 被动散热 | AR29: 250W
A30: A40 | B30: Ampere | C30: GA102 (Ampere) | D30: 数据中心 | E30: 10752 | F30: 336 | G30: 37.4 | H30: 37.4 | I30: 149.7 | J30: 299.3 | K30: 74.8 | L30: 149.7 | M30: 0.58 | O30: 598.6 | P30: 1197 | Q30: INT4 | R30: 48 | S30: 696 | T30: 300 | U30: A40 依托于 NVIDIA Ampere 架构而构建，将新一代 RT Core、Tensor Core、CUDA® Core 与 48GB 显存融于一身，可提供远超以往的图形处理、渲染、计算和 AI 性能。 | X30: GA102 (Ampere) | Y30: 10752 | Z30: 336 | AA30: 1300MHz | AB30: 1740MHz | AC30: 14.5GHz GDDR6 | AD30: 384-bit | AE30: 696 GB/sec | AF30: 48GB | AG30: 37.4 TFLOPS | AH30: 149.7 | 299.3 TFLOPS² | AI30: 37.4 TFLOPS | AJ30: 74.8 | 149.7 TFLOPS² | AK30: 0.58 TFLOPS | AL30: - | AM30: 299.3 | 598.6 TOPS² | AN30: 598.6 | 1,197 TOPS² | AO30: 112GB/sec (NVLink 3.0 2-way) | AP30: Samsung 8N 28.3B | AQ30: PCIe4.0 双槽位 被动散热 | AR30: 300W (系统供电: 700W)
A31: A30 | B31: Ampere | C31: GA100（Ampere） | D31: 数据中心 | E31: 3584 | F31: 224 | G31: 10.3 | H31: 41.2 | I31: 165 | J31: 330 | K31: 82.5 | L31: 165 | M31: 5.2 | N31: 10.3 | O31: 661 | P31: 1321 | Q31: INT4 | R31: 24 | S31: 933 | T31: 165 | U31: 新引入FP64, TF32, BF16 Tensor Core, 支持MIG, 深度学习/HPC大规模算例并行加速计算 | X31: GA100（Ampere） | Y31: 3584 | Z31: 224 | AA31: 930MHz | AB31: 1440MHz | AC31: 2.4GHz HBM2 | AD31: 3072-bit | AE31: 933GB/sec | AF31: 24GB | AG31: 41.2 TFLOPS | AH31: 165 | 330 TFLOPS² | AI31: 10.3 TFLOPS | AJ31: 82.5 | 165 TFLOPS² | AK31: 5.2 TFLOPS | AL31: 10.3 TFLOPS | AM31: 330 | 661 TOPS² | AN31: 661 | 1,321 TOPS² | AO31: 200GB/sec (NVLink 3.0 2-way) | AP31: 7nm N7, 54.2B | AQ31: PCIe4.0 双槽位 被动散热 | AR31: 165W
A32: A10 | B32: Ampere | C32: GA102（Ampere） | D32: 数据中心 | E32: 9216 | F32: 288 | G32: 31.2 | H32: 31.2 | I32: 125 | J32: 250 | K32: 62.5 | L32: 125 | M32: 0.97 | O32: 500 | P32: 1000 | Q32: INT4 | R32: 24 | S32: 600 | T32: 150 | U32: 外形小巧，低功耗，实时推理计算，适合大规模部署 | V32: 大批量视频编解码 | X32: GA102（Ampere） | Y32: 9216 | Z32: 288 | AA32: 885MHz | AB32: 1695MHz | AC32: GDDR6 | AE32: 600GB/sec | AF32: 24GB | AG32: 31.2 TFLOPS | AH32: 125 | 250 TFLOPS² | AI32: 31.2 TFLOPS | AJ32: 62.5 | 125 TFLOPS² | AK32: 0.97 TFLOPS | AL32: - | AM32: 250 | 500 TOPS² | AN32: 500 | 1,000 TOPS² | AO32: 64GB/sec | AQ32: PCIe4.0 单槽位 被动散热 | AR32: 150W
A33: RTX A6000 | B33: Ampere | C33: GA102 (Ampere) | D33: 专业工作站 | E33: 10752 | F33: 336 | G33: 38.7 | H33: 38.7 | I33: 154.8 | J33: 309.7 | K33: 77.4 | L33: 154.8 | M33: 0.61 | O33: 619.4 | P33: 1238.7 | Q33: INT4 | R33: 48 | S33: 768 | T33: 300 | U33: 3D渲染，图形设计，视频编辑，CAD/CAM, VR | W33: 深度学习 | X33: GA102 (Ampere) | Y33: 10752 | Z33: 336 | AA33: 1450MHz | AB33: 1800MHz | AC33: 16Gbps GDDR6 | AD33: 384-bit | AE33: 768 GB/sec | AF33: 48 GB | AG33: 38.7 TFLOPS | AH33: 154.8 | 309.7 TFLOPS² | AI33: 38.7 TFLOPS | AJ33: 77.4 | 154.8 TFLOPS² | AK33: 0.61 TFLOPS | AL33: - | AM33: 309.7 | 619.4 TOPS² | AN33: 619.4 | 1,238.7 TOPS² | AO33: 112GB/sec (NVLink 3.0 2-way) | AP33: Samsung 8N 28.3B | AQ33: PCIe4.0 双槽位 单涡轮风扇 主动散热 | AR33: 300W (系统供电: 700W)
A34: RTX 3090 | B34: Ampere | C34: GA102 (Ampere) | D34: 消费级 | E34: 10496 | F34: 328 | G34: 35.6 | H34: 35.6 | I34: 142.4 | J34: 284.7 | K34: 71.2 | L34: 142.4 | M34: 0.56 | O34: 569.4 | P34: 1138.9 | Q34: INT4 | R34: 24 | S34: 935 | T34: 350 | U34: 深度学习 | V34: RTX (实时光线追踪) | W34: VR | X34: GA102 (Ampere) | Y34: 10496 | Z34: 328 | AA34: 1395 MHz | AB34: 1695 MHz | AC34: 19Gbps GDDR6X | AD34: 384-bit | AE34: 935 GB/sec | AF34: 24GB | AG34: 35.6 TFLOPS | AH34: 142.4 | 284.7 TFLOPS² | AI34: 35.6 TFLOPS | AJ34: 71.2 | 142.4 TFLOPS² | AK34: 0.56 TFLOPS | AL34: - | AM34: 284.7 | 569.4 TOPS² | AN34: 569.4 | 1,138.9 TOPS² | AO34: 112GB/sec (NVLink 3.0 2-way, SLI only) | AP34: Samsung 8N 28.3B | AQ34: PCIe4.0 三槽位 正反双风扇 主动散热 | AR34: 350W (系统供电: 750W)
A35: RTX 3080 | B35: Ampere | C35: GA102 (Ampere) | D35: 消费级 | E35: 8704 | F35: 272 | G35: 29.8 | H35: 29.8 | I35: 119.1 | J35: 238.2 | K35: 59.5 | L35: 119.1 | M35: 0.47 | O35: 476.4 | P35: 952.8 | Q35: INT4 | R35: 10 | S35: 760 | T35: 320 | U35: 深度学习 | V35: RTX (实时光线追踪) | W35: VR | X35: GA102 (Ampere) | Y35: 8704 | Z35: 272 | AA35: 1440 MHz | AB35: 1710 MHz | AC35: 19Gbps GDDR6X | AD35: 320-bit | AE35: 760 GB/sec | AF35: 10GB | AG35: 29.8 TFLOPS | AH35: 119.1 | 238.2 TFLOPS² | AI35: 29.8 TFLOPS | AJ35: 59.5 | 119.1 TFLOPS² | AK35: 0.47 TFLOPS | AL35: - | AM35: 238.2 | 476.4 TOPS² | AN35: 476.4 | 952.8 TOPS² | AO35: PCIe 4.0 64GB/sec | AP35: Samsung 8N 28.3B | AQ35: PCIe4.0 双槽位 正反双风扇 主动散热 | AR35: 320W (系统供电: 750W)
A36: RTX 3070 | B36: Ampere | C36: GA104 (Ampere) | D36: 消费级 | E36: 5888 | F36: 184 | G36: 20.3 | H36: 20.3 | I36: 81.3 | J36: 162.6 | K36: 40.6 | L36: 81.3 | M36: 0.32 | O36: 325.2 | P36: 650.4 | Q36: INT4 | R36: 8 | S36: 448 | T36: 220 | U36: 深度学习 | V36: RTX (实时光线追踪) | W36: VR | X36: GA104 (Ampere) | Y36: 5888 | Z36: 184 | AA36: 1500 MHz | AB36: 1725 MHz | AC36: 14Gbps GDDR6 | AD36: 256-bit | AE36: 448 GB/s | AF36: 8GB | AG36: 20.3 TFLOPS | AH36: 81.3 | 162.6 TFLOPS² | AI36: 20.3 TFLOPS | AJ36: 40.6 | 81.3 TFLOPS² | AK36: 0.32 TFLOPS | AL36: - | AM36: 162.6 | 325.2 TOPS² | AN36: 325.2 | 650.4 TOPS² | AO36: PCIe 4.0 64GB/sec | AP36: Samsung 8N 17.4B | AQ36: PCIe4.0 双槽位 双风扇 主动散热 | AR36: 220W (系统供电: 650W)
A37: T4 | B37: Turing | C37: TU104 (Turing) | D37: 数据中心 | E37: 2560 | F37: 320 | G37: 8.1 | H37: 16.2 | I37: 65 | M37: 0.25 | O37: 130 | P37: 260 | Q37: INT4 | R37: 16 | S37: 320 | T37: 75 | U37: 小型，低功耗，实时推理计算，大规模部署 | V37: 大批量视频编解码 | X37: TU104 (Turing) | Y37: 2560 | Z37: 320 | AA37: 660 MHz | AB37: 1590 MHz | AC37: 10Gbps GDDR6 | AD37: 256-bit | AE37: 320GB/sec | AF37: 16GB | AG37: 16.2 TFLOPS | AH37: 65 TFLOPS | AI37: 8.1 TFLOPS | AJ37: - | AK37: 0.25 TFLOPS | AL37: - | AM37: 130 TOPS | AN37: 260 TOPS | AO37: 32GB/sec | AP37: 12nm FFN, 13.6B | AQ37: PCIe 单槽位 被动散热 | AR37: 75W
A38: RTX 8000（主动散热） | B38: Turing | C38: TU102 (Turing) | D38: 专业工作站 | E38: 4608 | F38: 576 | G38: 16.3 | H38: 32.6 | I38: 130.5 | M38: 0.51 | O38: 261 | P38: 522 | Q38: INT4 | R38: 48 | S38: 672 | T38: 260 | U38: 3D渲染，图形设计，视频编辑，CAD/CAM, VR | W38: 深度学习 | X38: TU102 (Turing) | Y38: 4608 | Z38: 576 | AA38: 1350MHz | AB38: 1630MHz | AC38: 14Gbps GDDR6 | AD38: 384-bit | AE38: 672 GB/sec | AF38: 48GB | AG38: 32.6 TFLOPS | AH38: 130.5 TFLOPS | AI38: 16.3 TFLOPS | AJ38: - | AK38: 0.51 TFLOPS | AL38: - | AM38: 261 TOPS | AN38: 522 TOPS | AO38: 100GB/sec (NVLink 2.0 2-way) | AP38: 18.6B | AQ38: PCIe 双槽位 单涡轮风扇 主动散热 | AR38: 260W (系统供电: 650W)
A39: RTX 8000（被动散热） | B39: Turing | C39: TU102 (Turing) | D39: 专业工作站 | E39: 4608 | F39: 576 | G39: 14.9 | H39: 29.9 | I39: 119 | M39: 0.47 | O39: 238 | P39: 477 | Q39: INT4 | R39: 48 | S39: 624 | T39: 250 | U39: 3D渲染，图形设计，视频编辑，CAD/CAM, VR | W39: 深度学习 | X39: TU102 (Turing) | Y39: 4608 | Z39: 576 | AA39: 1230 MHz | AB39: 1620 MHz | AC39: 14Gbps GDDR6 | AD39: 384-bit | AE39: 624 GB/sec | AF39: 48GB | AG39: 29.9 TFLOPS | AH39: ≈119 TFLOPS | AI39: 14.9 TFLOPS | AJ39: - | AK39: 0.47 TFLOPS | AL39: - | AM39: ≈238 TOPS | AN39: ≈477 TOPS | AO39: 100GB/sec (NVLink 2.0 2-way) | AP39: 18.6B | AQ39: PCIe 双槽位 被动散热 | AR39: 250W
A40: RTX 6000（主动散热） | B40: Turing | C40: TU102 (Turing) | D40: 专业工作站 | E40: 4608 | F40: 576 | G40: 16.3 | H40: 32.6 | I40: 130.5 | M40: 0.51 | O40: 261 | P40: 522 | Q40: INT4 | R40: 24 | S40: 672 | T40: 260 | U40: 3D渲染，图形设计，视频编辑，CAD/CAM, VR | W40: 深度学习 | X40: TU102 (Turing) | Y40: 4608 | Z40: 576 | AA40: 1455MHz | AB40: 1770MHz | AC40: 14Gbps GDDR6 | AD40: 384-bit | AE40: 672 GB/sec | AF40: 24GB | AG40: 32.6 TFLOPS | AH40: 130.5 TFLOPS | AI40: 16.3 TFLOPS | AJ40: - | AK40: 0.51 TFLOPS | AL40: - | AM40: 261 TOPS | AN40: 522 TOPS | AO40: 100GB/sec (NVLink 2.0 2-way) | AP40: 18.6B | AQ40: PCIe 双槽位 单涡轮风扇 主动散热 | AR40: 260W (系统供电: 650W)
...

Sheet 选型对比
B2: GPU 选型对比工具（下拉选择，自动对比）
B3: 使用方法：在第 6 行黄色单元格中下拉选择 3~6 款型号（至少 3 款），下方参数表、数值指标与柱状图将自动更新。
B4: 数据来源：「参数对比」表；算力标记 ²=稀疏口径，*=稀疏口径，≈=推算值。型号含重名列（A40、RTX 8000、RTX 6000）时下拉选择任一即可（参数相同）。
B6: 对比型号 → | C6: B300 SXM | D6: B200 SXM | E6: H100 SXM | F6: GB300 NVL72
B7: （红色为建议必选的前 3 款）
B9: 参数 | C9: =IF(C$6="","",C$6) -> B300 SXM | D9: =IF(D$6="","",D$6) -> B200 SXM | E9: =IF(E$6="","",E$6) -> H100 SXM | F9: =IF(F$6="","",F$6) -> GB300 NVL72 | G9: =IF(G$6="","",G$6) | H9: =IF(H$6="","",H$6)
B10: =速览对比!$U$1 -> Target Markets / 目标市场 | C10: =IF(C$6="","",IFERROR(IF(ISTEXT(INDEX(速览对比!$U$2:$U$63,MATCH(C$6,速览对比!$A$2:$A$63,0))),INDEX(速览对比!$U$2:$U$63,MATCH(C$6,速览对比!$A$2:$A$63,0)),IF(INDEX(速览对比!$U$2:$U$63,MATCH(C$6,速览对比!$A$2:$A$63,0))=0,"",INDEX(速览对比!$U$2:$U$63,MATCH(C$6,速览对比!$A$2:$A$63,0)))),"-")) -> 2025年3月GTC发布的Blackwell Ultra架构GPU（GB100双芯粒，TSMC 4NP，2080亿晶体管）：288GB HBM3e显存、8TB/s带宽，FP4稠密算力较B200提升50%，attention吞吐约2倍。面向万亿参数大模型训练、长上下文推理与AI工厂（HGX B300 / DGX B300 / GB300 NVL72），需液冷 | D10: =IF(D$6="","",IFERROR(IF(ISTEXT(INDEX(速览对比!$U$2:$U$63,MATCH(D$6,速览对比!$A$2:$A$63,0))),INDEX(速览对比!$U$2:$U$63,MATCH(D$6,速览对比!$A$2:$A$63,0)),IF(INDEX(速览对比!$U$2:$U$63,MATCH(D$6,速览对比!$A$2:$A$63,0))=0,"",INDEX(速览对比!$U$2:$U$63,MATCH(D$6,速览对比!$A$2:$A$63,0)))),"-")) -> 这是一款采用台积电4NP工艺的GPU，采用NVIDIA Blackwell架构，上市时间为2024年。具有2080亿个晶体管、16896个CUDA核心和192GB HBM3e显存，FP32算力75 TFLOPS，总功耗为1000W。 | E10: =IF(E$6="","",IFERROR(IF(ISTEXT(INDEX(速览对比!$U$2:$U$63,MATCH(E$6,速览对比!$A$2:$A$63,0))),INDEX(速览对比!$U$2:$U$63,MATCH(E$6,速览对比!$A$2:$A$63,0)),IF(INDEX(速览对比!$U$2:$U$63,MATCH(E$6,速览对比!$A$2:$A$63,0))=0,"",INDEX(速览对比!$U$2:$U$63,MATCH(E$6,速览对比!$A$2:$A$63,0)))),"-")) -> H100 是全球范围内最大的性能出众的加速器，拥有革命性的 Transformer 引擎和高度可扩展的 NVIDIA NVLink® 互连技术等突破性功能，可推动庞大的 AI 语言模型、深度推荐系统、基因组学和复杂数字孪生的发展 | F10: =IF(F$6="","",IFERROR(IF(ISTEXT(INDEX(速览对比!$U$2:$U$63,MATCH(F$6,速览对比!$A$2:$A$63,0))),INDEX(速览对比!$U$2:$U$63,MATCH(F$6,速览对比!$A$2:$A$63,0)),IF(INDEX(速览对比!$U$2:$U$63,MATCH(F$6,速览对比!$A$2:$A$63,0))=0,"",INDEX(速览对比!$U$2:$U$63,MATCH(F$6,速览对比!$A$2:$A$63,0)))),"-")) -> 数据中心（AI 工厂 / 机柜级方案） | G10: =IF(G$6="","",IFERROR(IF(ISTEXT(INDEX(速览对比!$U$2:$U$63,MATCH(G$6,速览对比!$A$2:$A$63,0))),INDEX(速览对比!$U$2:$U$63,MATCH(G$6,速览对比!$A$2:$A$63,0)),IF(INDEX(速览对比!$U$2:$U$63,MATCH(G$6,速览对比!$A$2:$A$63,0))=0,"",INDEX(速览对比!$U$2:$U$63,MATCH(G$6,速览对比!$A$2:$A$63,0)))),"-")) | H10: =IF(H$6="","",IFERROR(IF(ISTEXT(INDEX(速览对比!$U$2:$U$63,MATCH(H$6,速览对比!$A$2:$A$63,0))),INDEX(速览对比!$U$2:$U$63,MATCH(H$6,速览对比!$A$2:$A$63,0)),IF(INDEX(速览对比!$U$2:$U$63,MATCH(H$6,速览对比!$A$2:$A$63,0))=0,"",INDEX(速览对比!$U$2:$U$63,MATCH(H$6,速览对比!$A$2:$A$63,0)))),"-"))
B11: 目标市场（细分 2） | C11: =IF(C$6="","",IFERROR(IF(ISTEXT(INDEX(速览对比!$V$2:$V$63,MATCH(C$6,速览对比!$A$2:$A$63,0))),INDEX(速览对比!$V$2:$V$63,MATCH(C$6,速览对比!$A$2:$A$63,0)),IF(INDEX(速览对比!$V$2:$V$63,MATCH(C$6,速览对比!$A$2:$A$63,0))=0,"",INDEX(速览对比!$V$2:$V$63,MATCH(C$6,速览对比!$A$2:$A$63,0)))),"-")) | D11: =IF(D$6="","",IFERROR(IF(ISTEXT(INDEX(速览对比!$V$2:$V$63,MATCH(D$6,速览对比!$A$2:$A$63,0))),INDEX(速览对比!$V$2:$V$63,MATCH(D$6,速览对比!$A$2:$A$63,0)),IF(INDEX(速览对比!$V$2:$V$63,MATCH(D$6,速览对比!$A$2:$A$63,0))=0,"",INDEX(速览对比!$V$2:$V$63,MATCH(D$6,速览对比!$A$2:$A$63,0)))),"-")) | E11: =IF(E$6="","",IFERROR(IF(ISTEXT(INDEX(速览对比!$V$2:$V$63,MATCH(E$6,速览对比!$A$2:$A$63,0))),INDEX(速览对比!$V$2:$V$63,MATCH(E$6,速览对比!$A$2:$A$63,0)),IF(INDEX(速览对比!$V$2:$V$63,MATCH(E$6,速览对比!$A$2:$A$63,0))=0,"",INDEX(速览对比!$V$2:$V$63,MATCH(E$6,速览对比!$A$2:$A$63,0)))),"-")) | F11: =IF(F$6="","",IFERROR(IF(ISTEXT(INDEX(速览对比!$V$2:$V$63,MATCH(F$6,速览对比!$A$2:$A$63,0))),INDEX(速览对比!$V$2:$V$63,MATCH(F$6,速览对比!$A$2:$A$63,0)),IF(INDEX(速览对比!$V$2:$V$63,MATCH(F$6,速览对比!$A$2:$A$63,0))=0,"",INDEX(速览对比!$V$2:$V$63,MATCH(F$6,速览对比!$A$2:$A$63,0)))),"-")) | G11: =IF(G$6="","",IFERROR(IF(ISTEXT(INDEX(速览对比!$V$2:$V$63,MATCH(G$6,速览对比!$A$2:$A$63,0))),INDEX(速览对比!$V$2:$V$63,MATCH(G$6,速览对比!$A$2:$A$63,0)),IF(INDEX(速览对比!$V$2:$V$63,MATCH(G$6,速览对比!$A$2:$A$63,0))=0,"",INDEX(速览对比!$V$2:$V$63,MATCH(G$6,速览对比!$A$2:$A$63,0)))),"-")) | H11: =IF(H$6="","",IFERROR(IF(ISTEXT(INDEX(速览对比!$V$2:$V$63,MATCH(H$6,速览对比!$A$2:$A$63,0))),INDEX(速览对比!$V$2:$V$63,MATCH(H$6,速览对比!$A$2:$A$63,0)),IF(INDEX(速览对比!$V$2:$V$63,MATCH(H$6,速览对比!$A$2:$A$63,0))=0,"",INDEX(速览对比!$V$2:$V$63,MATCH(H$6,速览对比!$A$2:$A$63,0)))),"-"))
B12: 目标市场（细分 3） | C12: =IF(C$6="","",IFERROR(IF(ISTEXT(INDEX(速览对比!$W$2:$W$63,MATCH(C$6,速览对比!$A$2:$A$63,0))),INDEX(速览对比!$W$2:$W$63,MATCH(C$6,速览对比!$A$2:$A$63,0)),IF(INDEX(速览对比!$W$2:$W$63,MATCH(C$6,速览对比!$A$2:$A$63,0))=0,"",INDEX(速览对比!$W$2:$W$63,MATCH(C$6,速览对比!$A$2:$A$63,0)))),"-")) | D12: =IF(D$6="","",IFERROR(IF(ISTEXT(INDEX(速览对比!$W$2:$W$63,MATCH(D$6,速览对比!$A$2:$A$63,0))),INDEX(速览对比!$W$2:$W$63,MATCH(D$6,速览对比!$A$2:$A$63,0)),IF(INDEX(速览对比!$W$2:$W$63,MATCH(D$6,速览对比!$A$2:$A$63,0))=0,"",INDEX(速览对比!$W$2:$W$63,MATCH(D$6,速览对比!$A$2:$A$63,0)))),"-")) | E12: =IF(E$6="","",IFERROR(IF(ISTEXT(INDEX(速览对比!$W$2:$W$63,MATCH(E$6,速览对比!$A$2:$A$63,0))),INDEX(速览对比!$W$2:$W$63,MATCH(E$6,速览对比!$A$2:$A$63,0)),IF(INDEX(速览对比!$W$2:$W$63,MATCH(E$6,速览对比!$A$2:$A$63,0))=0,"",INDEX(速览对比!$W$2:$W$63,MATCH(E$6,速览对比!$A$2:$A$63,0)))),"-")) | F12: =IF(F$6="","",IFERROR(IF(ISTEXT(INDEX(速览对比!$W$2:$W$63,MATCH(F$6,速览对比!$A$2:$A$63,0))),INDEX(速览对比!$W$2:$W$63,MATCH(F$6,速览对比!$A$2:$A$63,0)),IF(INDEX(速览对比!$W$2:$W$63,MATCH(F$6,速览对比!$A$2:$A$63,0))=0,"",INDEX(速览对比!$W$2:$W$63,MATCH(F$6,速览对比!$A$2:$A$63,0)))),"-")) | G12: =IF(G$6="","",IFERROR(IF(ISTEXT(INDEX(速览对比!$W$2:$W$63,MATCH(G$6,速览对比!$A$2:$A$63,0))),INDEX(速览对比!$W$2:$W$63,MATCH(G$6,速览对比!$A$2:$A$63,0)),IF(INDEX(速览对比!$W$2:$W$63,MATCH(G$6,速览对比!$A$2:$A$63,0))=0,"",INDEX(速览对比!$W$2:$W$63,MATCH(G$6,速览对比!$A$2:$A$63,0)))),"-")) | H12: =IF(H$6="","",IFERROR(IF(ISTEXT(INDEX(速览对比!$W$2:$W$63,MATCH(H$6,速览对比!$A$2:$A$63,0))),INDEX(速览对比!$W$2:$W$63,MATCH(H$6,速览对比!$A$2:$A$63,0)),IF(INDEX(速览对比!$W$2:$W$63,MATCH(H$6,速览对比!$A$2:$A$63,0))=0,"",INDEX(速览对比!$W$2:$W$63,MATCH(H$6,速览对比!$A$2:$A$63,0)))),"-"))
B13: =速览对比!$X$1 -> GPU / 图形处理单元（架构） | C13: =IF(C$6="","",IFERROR(IF(ISTEXT(INDEX(速览对比!$X$2:$X$63,MATCH(C$6,速览对比!$A$2:$A$63,0))),INDEX(速览对比!$X$2:$X$63,MATCH(C$6,速览对比!$A$2:$A$63,0)),IF(INDEX(速览对比!$X$2:$X$63,MATCH(C$6,速览对比!$A$2:$A$63,0))=0,"",INDEX(速览对比!$X$2:$X$63,MATCH(C$6,速览对比!$A$2:$A$63,0)))),"-")) -> GB300（Blackwell Ultra） | D13: =IF(D$6="","",IFERROR(IF(ISTEXT(INDEX(速览对比!$X$2:$X$63,MATCH(D$6,速览对比!$A$2:$A$63,0))),INDEX(速览对比!$X$2:$X$63,MATCH(D$6,速览对比!$A$2:$A$63,0)),IF(INDEX(速览对比!$X$2:$X$63,MATCH(D$6,速览对比!$A$2:$A$63,0))=0,"",INDEX(速览对比!$X$2:$X$63,MATCH(D$6,速览对比!$A$2:$A$63,0)))),"-")) -> GB100（Blackwell，双芯粒） | E13: =IF(E$6="","",IFERROR(IF(ISTEXT(INDEX(速览对比!$X$2:$X$63,MATCH(E$6,速览对比!$A$2:$A$63,0))),INDEX(速览对比!$X$2:$X$63,MATCH(E$6,速览对比!$A$2:$A$63,0)),IF(INDEX(速览对比!$X$2:$X$63,MATCH(E$6,速览对比!$A$2:$A$63,0))=0,"",INDEX(速览对比!$X$2:$X$63,MATCH(E$6,速览对比!$A$2:$A$63,0)))),"-")) -> GH100（Hopper） | F13: =IF(F$6="","",IFERROR(IF(ISTEXT(INDEX(速览对比!$X$2:$X$63,MATCH(F$6,速览对比!$A$2:$A$63,0))),INDEX(速览对比!$X$2:$X$63,MATCH(F$6,速览对比!$A$2:$A$63,0)),IF(INDEX(速览对比!$X$2:$X$63,MATCH(F$6,速览对比!$A$2:$A$63,0))=0,"",INDEX(速览对比!$X$2:$X$63,MATCH(F$6,速览对比!$A$2:$A$63,0)))),"-")) -> GB300（Blackwell Ultra） | G13: =IF(G$6="","",IFERROR(IF(ISTEXT(INDEX(速览对比!$X$2:$X$63,MATCH(G$6,速览对比!$A$2:$A$63,0))),INDEX(速览对比!$X$2:$X$63,MATCH(G$6,速览对比!$A$2:$A$63,0)),IF(INDEX(速览对比!$X$2:$X$63,MATCH(G$6,速览对比!$A$2:$A$63,0))=0,"",INDEX(速览对比!$X$2:$X$63,MATCH(G$6,速览对比!$A$2:$A$63,0)))),"-")) | H13: =IF(H$6="","",IFERROR(IF(ISTEXT(INDEX(速览对比!$X$2:$X$63,MATCH(H$6,速览对比!$A$2:$A$63,0))),INDEX(速览对比!$X$2:$X$63,MATCH(H$6,速览对比!$A$2:$A$63,0)),IF(INDEX(速览对比!$X$2:$X$63,MATCH(H$6,速览对比!$A$2:$A$63,0))=0,"",INDEX(速览对比!$X$2:$X$63,MATCH(H$6,速览对比!$A$2:$A$63,0)))),"-"))
B14: =速览对比!$Y$1 -> GPU Cores / CUDA 单元数 | C14: =IF(C$6="","",IFERROR(IF(ISTEXT(INDEX(速览对比!$Y$2:$Y$63,MATCH(C$6,速览对比!$A$2:$A$63,0))),INDEX(速览对比!$Y$2:$Y$63,MATCH(C$6,速览对比!$A$2:$A$63,0)),IF(INDEX(速览对比!$Y$2:$Y$63,MATCH(C$6,速览对比!$A$2:$A$63,0))=0,"",INDEX(速览对比!$Y$2:$Y$63,MATCH(C$6,速览对比!$A$2:$A$63,0)))),"-")) -> 16896 | D14: =IF(D$6="","",IFERROR(IF(ISTEXT(INDEX(速览对比!$Y$2:$Y$63,MATCH(D$6,速览对比!$A$2:$A$63,0))),INDEX(速览对比!$Y$2:$Y$63,MATCH(D$6,速览对比!$A$2:$A$63,0)),IF(INDEX(速览对比!$Y$2:$Y$63,MATCH(D$6,速览对比!$A$2:$A$63,0))=0,"",INDEX(速览对比!$Y$2:$Y$63,MATCH(D$6,速览对比!$A$2:$A$63,0)))),"-")) -> 16896 | E14: =IF(E$6="","",IFERROR(IF(ISTEXT(INDEX(速览对比!$Y$2:$Y$63,MATCH(E$6,速览对比!$A$2:$A$63,0))),INDEX(速览对比!$Y$2:$Y$63,MATCH(E$6,速览对比!$A$2:$A$63,0)),IF(INDEX(速览对比!$Y$2:$Y$63,MATCH(E$6,速览对比!$A$2:$A$63,0))=0,"",INDEX(速览对比!$Y$2:$Y$63,MATCH(E$6,速览对比!$A$2:$A$63,0)))),"-")) -> 16896 | F14: =IF(F$6="","",IFERROR(IF(ISTEXT(INDEX(速览对比!$Y$2:$Y$63,MATCH(F$6,速览对比!$A$2:$A$63,0))),INDEX(速览对比!$Y$2:$Y$63,MATCH(F$6,速览对比!$A$2:$A$63,0)),IF(INDEX(速览对比!$Y$2:$Y$63,MATCH(F$6,速览对比!$A$2:$A$63,0))=0,"",INDEX(速览对比!$Y$2:$Y$63,MATCH(F$6,速览对比!$A$2:$A$63,0)))),"-")) -> 16896（每GPU） | G14: =IF(G$6="","",IFERROR(IF(ISTEXT(INDEX(速览对比!$Y$2:$Y$63,MATCH(G$6,速览对比!$A$2:$A$63,0))),INDEX(速览对比!$Y$2:$Y$63,MATCH(G$6,速览对比!$A$2:$A$63,0)),IF(INDEX(速览对比!$Y$2:$Y$63,MATCH(G$6,速览对比!$A$2:$A$63,0))=0,"",INDEX(速览对比!$Y$2:$Y$63,MATCH(G$6,速览对比!$A$2:$A$63,0)))),"-")) | H14: =IF(H$6="","",IFERROR(IF(ISTEXT(INDEX(速览对比!$Y$2:$Y$63,MATCH(H$6,速览对比!$A$2:$A$63,0))),INDEX(速览对比!$Y$2:$Y$63,MATCH(H$6,速览对比!$A$2:$A$63,0)),IF(INDEX(速览对比!$Y$2:$Y$63,MATCH(H$6,速览对比!$A$2:$A$63,0))=0,"",INDEX(速览对比!$Y$2:$Y$63,MATCH(H$6,速览对比!$A$2:$A$63,0)))),"-"))
B15: =速览对比!$Z$1 -> Tensor Cores / Tensor 核数 | C15: =IF(C$6="","",IFERROR(IF(ISTEXT(INDEX(速览对比!$Z$2:$Z$63,MATCH(C$6,速览对比!$A$2:$A$63,0))),INDEX(速览对比!$Z$2:$Z$63,MATCH(C$6,速览对比!$A$2:$A$63,0)),IF(INDEX(速览对比!$Z$2:$Z$63,MATCH(C$6,速览对比!$A$2:$A$63,0))=0,"",INDEX(速览对比!$Z$2:$Z$63,MATCH(C$6,速览对比!$A$2:$A$63,0)))),"-")) -> 528 | D15: =IF(D$6="","",IFERROR(IF(ISTEXT(INDEX(速览对比!$Z$2:$Z$63,MATCH(D$6,速览对比!$A$2:$A$63,0))),INDEX(速览对比!$Z$2:$Z$63,MATCH(D$6,速览对比!$A$2:$A$63,0)),IF(INDEX(速览对比!$Z$2:$Z$63,MATCH(D$6,速览对比!$A$2:$A$63,0))=0,"",INDEX(速览对比!$Z$2:$Z$63,MATCH(D$6,速览对比!$A$2:$A$63,0)))),"-")) -> 528 | E15: =IF(E$6="","",IFERROR(IF(ISTEXT(INDEX(速览对比!$Z$2:$Z$63,MATCH(E$6,速览对比!$A$2:$A$63,0))),INDEX(速览对比!$Z$2:$Z$63,MATCH(E$6,速览对比!$A$2:$A$63,0)),IF(INDEX(速览对比!$Z$2:$Z$63,MATCH(E$6,速览对比!$A$2:$A$63,0))=0,"",INDEX(速览对比!$Z$2:$Z$63,MATCH(E$6,速览对比!$A$2:$A$63,0)))),"-")) -> 528 | F15: =IF(F$6="","",IFERROR(IF(ISTEXT(INDEX(速览对比!$Z$2:$Z$63,MATCH(F$6,速览对比!$A$2:$A$63,0))),INDEX(速览对比!$Z$2:$Z$63,MATCH(F$6,速览对比!$A$2:$A$63,0)),IF(INDEX(速览对比!$Z$2:$Z$63,MATCH(F$6,速览对比!$A$2:$A$63,0))=0,"",INDEX(速览对比!$Z$2:$Z$63,MATCH(F$6,速览对比!$A$2:$A$63,0)))),"-")) -> 528（每GPU） | G15: =IF(G$6="","",IFERROR(IF(ISTEXT(INDEX(速览对比!$Z$2:$Z$63,MATCH(G$6,速览对比!$A$2:$A$63,0))),INDEX(速览对比!$Z$2:$Z$63,MATCH(G$6,速览对比!$A$2:$A$63,0)),IF(INDEX(速览对比!$Z$2:$Z$63,MATCH(G$6,速览对比!$A$2:$A$63,0))=0,"",INDEX(速览对比!$Z$2:$Z$63,MATCH(G$6,速览对比!$A$2:$A$63,0)))),"-")) | H15: =IF(H$6="","",IFERROR(IF(ISTEXT(INDEX(速览对比!$Z$2:$Z$63,MATCH(H$6,速览对比!$A$2:$A$63,0))),INDEX(速览对比!$Z$2:$Z$63,MATCH(H$6,速览对比!$A$2:$A$63,0)),IF(INDEX(速览对比!$Z$2:$Z$63,MATCH(H$6,速览对比!$A$2:$A$63,0))=0,"",INDEX(速览对比!$Z$2:$Z$63,MATCH(H$6,速览对比!$A$2:$A$63,0)))),"-"))
B16: =速览对比!$AA$1 -> Core Clock / 基本频率 | C16: =IF(C$6="","",IFERROR(IF(ISTEXT(INDEX(速览对比!$AA$2:$AA$63,MATCH(C$6,速览对比!$A$2:$A$63,0))),INDEX(速览对比!$AA$2:$AA$63,MATCH(C$6,速览对比!$A$2:$A$63,0)),IF(INDEX(速览对比!$AA$2:$AA$63,MATCH(C$6,速览对比!$A$2:$A$63,0))=0,"",INDEX(速览对比!$AA$2:$AA$63,MATCH(C$6,速览对比!$A$2:$A$63,0)))),"-")) -> - | D16: =IF(D$6="","",IFERROR(IF(ISTEXT(INDEX(速览对比!$AA$2:$AA$63,MATCH(D$6,速览对比!$A$2:$A$63,0))),INDEX(速览对比!$AA$2:$AA$63,MATCH(D$6,速览对比!$A$2:$A$63,0)),IF(INDEX(速览对比!$AA$2:$AA$63,MATCH(D$6,速览对比!$A$2:$A$63,0))=0,"",INDEX(速览对比!$AA$2:$AA$63,MATCH(D$6,速览对比!$A$2:$A$63,0)))),"-")) -> 1665 MHz | E16: =IF(E$6="","",IFERROR(IF(ISTEXT(INDEX(速览对比!$AA$2:$AA$63,MATCH(E$6,速览对比!$A$2:$A$63,0))),INDEX(速览对比!$AA$2:$AA$63,MATCH(E$6,速览对比!$A$2:$A$63,0)),IF(INDEX(速览对比!$AA$2:$AA$63,MATCH(E$6,速览对比!$A$2:$A$63,0))=0,"",INDEX(速览对比!$AA$2:$AA$63,MATCH(E$6,速览对比!$A$2:$A$63,0)))),"-")) -> 1590 MHz | F16: =IF(F$6="","",IFERROR(IF(ISTEXT(INDEX(速览对比!$AA$2:$AA$63,MATCH(F$6,速览对比!$A$2:$A$63,0))),INDEX(速览对比!$AA$2:$AA$63,MATCH(F$6,速览对比!$A$2:$A$63,0)),IF(INDEX(速览对比!$AA$2:$AA$63,MATCH(F$6,速览对比!$A$2:$A$63,0))=0,"",INDEX(速览对比!$AA$2:$AA$63,MATCH(F$6,速览对比!$A$2:$A$63,0)))),"-")) -> - | G16: =IF(G$6="","",IFERROR(IF(ISTEXT(INDEX(速览对比!$AA$2:$AA$63,MATCH(G$6,速览对比!$A$2:$A$63,0))),INDEX(速览对比!$AA$2:$AA$63,MATCH(G$6,速览对比!$A$2:$A$63,0)),IF(INDEX(速览对比!$AA$2:$AA$63,MATCH(G$6,速览对比!$A$2:$A$63,0))=0,"",INDEX(速览对比!$AA$2:$AA$63,MATCH(G$6,速览对比!$A$2:$A$63,0)))),"-")) | H16: =IF(H$6="","",IFERROR(IF(ISTEXT(INDEX(速览对比!$AA$2:$AA$63,MATCH(H$6,速览对比!$A$2:$A$63,0))),INDEX(速览对比!$AA$2:$AA$63,MATCH(H$6,速览对比!$A$2:$A$63,0)),IF(INDEX(速览对比!$AA$2:$AA$63,MATCH(H$6,速览对比!$A$2:$A$63,0))=0,"",INDEX(速览对比!$AA$2:$AA$63,MATCH(H$6,速览对比!$A$2:$A$63,0)))),"-"))
B17: =速览对比!$AB$1 -> Boost Clock(s) / 超频频率 | C17: =IF(C$6="","",IFERROR(IF(ISTEXT(INDEX(速览对比!$AB$2:$AB$63,MATCH(C$6,速览对比!$A$2:$A$63,0))),INDEX(速览对比!$AB$2:$AB$63,MATCH(C$6,速览对比!$A$2:$A$63,0)),IF(INDEX(速览对比!$AB$2:$AB$63,MATCH(C$6,速览对比!$A$2:$A$63,0))=0,"",INDEX(速览对比!$AB$2:$AB$63,MATCH(C$6,速览对比!$A$2:$A$63,0)))),"-")) -> - | D17: =IF(D$6="","",IFERROR(IF(ISTEXT(INDEX(速览对比!$AB$2:$AB$63,MATCH(D$6,速览对比!$A$2:$A$63,0))),INDEX(速览对比!$AB$2:$AB$63,MATCH(D$6,速览对比!$A$2:$A$63,0)),IF(INDEX(速览对比!$AB$2:$AB$63,MATCH(D$6,速览对比!$A$2:$A$63,0))=0,"",INDEX(速览对比!$AB$2:$AB$63,MATCH(D$6,速览对比!$A$2:$A$63,0)))),"-")) -> 1837 MHz | E17: =IF(E$6="","",IFERROR(IF(ISTEXT(INDEX(速览对比!$AB$2:$AB$63,MATCH(E$6,速览对比!$A$2:$A$63,0))),INDEX(速览对比!$AB$2:$AB$63,MATCH(E$6,速览对比!$A$2:$A$63,0)),IF(INDEX(速览对比!$AB$2:$AB$63,MATCH(E$6,速览对比!$A$2:$A$63,0))=0,"",INDEX(速览对比!$AB$2:$AB$63,MATCH(E$6,速览对比!$A$2:$A$63,0)))),"-")) -> 1980 MHz | F17: =IF(F$6="","",IFERROR(IF(ISTEXT(INDEX(速览对比!$AB$2:$AB$63,MATCH(F$6,速览对比!$A$2:$A$63,0))),INDEX(速览对比!$AB$2:$AB$63,MATCH(F$6,速览对比!$A$2:$A$63,0)),IF(INDEX(速览对比!$AB$2:$AB$63,MATCH(F$6,速览对比!$A$2:$A$63,0))=0,"",INDEX(速览对比!$AB$2:$AB$63,MATCH(F$6,速览对比!$A$2:$A$63,0)))),"-")) -> - | G17: =IF(G$6="","",IFERROR(IF(ISTEXT(INDEX(速览对比!$AB$2:$AB$63,MATCH(G$6,速览对比!$A$2:$A$63,0))),INDEX(速览对比!$AB$2:$AB$63,MATCH(G$6,速览对比!$A$2:$A$63,0)),IF(INDEX(速览对比!$AB$2:$AB$63,MATCH(G$6,速览对比!$A$2:$A$63,0))=0,"",INDEX(速览对比!$AB$2:$AB$63,MATCH(G$6,速览对比!$A$2:$A$63,0)))),"-")) | H17: =IF(H$6="","",IFERROR(IF(ISTEXT(INDEX(速览对比!$AB$2:$AB$63,MATCH(H$6,速览对比!$A$2:$A$63,0))),INDEX(速览对比!$AB$2:$AB$63,MATCH(H$6,速览对比!$A$2:$A$63,0)),IF(INDEX(速览对比!$AB$2:$AB$63,MATCH(H$6,速览对比!$A$2:$A$63,0))=0,"",INDEX(速览对比!$AB$2:$AB$63,MATCH(H$6,速览对比!$A$2:$A$63,0)))),"-"))
B18: =速览对比!$AC$1 -> Memory Clock / 显存频率 | C18: =IF(C$6="","",IFERROR(IF(ISTEXT(INDEX(速览对比!$AC$2:$AC$63,MATCH(C$6,速览对比!$A$2:$A$63,0))),INDEX(速览对比!$AC$2:$AC$63,MATCH(C$6,速览对比!$A$2:$A$63,0)),IF(INDEX(速览对比!$AC$2:$AC$63,MATCH(C$6,速览对比!$A$2:$A$63,0))=0,"",INDEX(速览对比!$AC$2:$AC$63,MATCH(C$6,速览对比!$A$2:$A$63,0)))),"-")) -> HBM3e | D18: =IF(D$6="","",IFERROR(IF(ISTEXT(INDEX(速览对比!$AC$2:$AC$63,MATCH(D$6,速览对比!$A$2:$A$63,0))),INDEX(速览对比!$AC$2:$AC$63,MATCH(D$6,速览对比!$A$2:$A$63,0)),IF(INDEX(速览对比!$AC$2:$AC$63,MATCH(D$6,速览对比!$A$2:$A$63,0))=0,"",INDEX(速览对比!$AC$2:$AC$63,MATCH(D$6,速览对比!$A$2:$A$63,0)))),"-")) -> 2000 MHz | E18: =IF(E$6="","",IFERROR(IF(ISTEXT(INDEX(速览对比!$AC$2:$AC$63,MATCH(E$6,速览对比!$A$2:$A$63,0))),INDEX(速览对比!$AC$2:$AC$63,MATCH(E$6,速览对比!$A$2:$A$63,0)),IF(INDEX(速览对比!$AC$2:$AC$63,MATCH(E$6,速览对比!$A$2:$A$63,0))=0,"",INDEX(速览对比!$AC$2:$AC$63,MATCH(E$6,速览对比!$A$2:$A$63,0)))),"-")) -> 2.6 GHz HBM3 | F18: =IF(F$6="","",IFERROR(IF(ISTEXT(INDEX(速览对比!$AC$2:$AC$63,MATCH(F$6,速览对比!$A$2:$A$63,0))),INDEX(速览对比!$AC$2:$AC$63,MATCH(F$6,速览对比!$A$2:$A$63,0)),IF(INDEX(速览对比!$AC$2:$AC$63,MATCH(F$6,速览对比!$A$2:$A$63,0))=0,"",INDEX(速览对比!$AC$2:$AC$63,MATCH(F$6,速览对比!$A$2:$A$63,0)))),"-")) -> HBM3e | G18: =IF(G$6="","",IFERROR(IF(ISTEXT(INDEX(速览对比!$AC$2:$AC$63,MATCH(G$6,速览对比!$A$2:$A$63,0))),INDEX(速览对比!$AC$2:$AC$63,MATCH(G$6,速览对比!$A$2:$A$63,0)),IF(INDEX(速览对比!$AC$2:$AC$63,MATCH(G$6,速览对比!$A$2:$A$63,0))=0,"",INDEX(速览对比!$AC$2:$AC$63,MATCH(G$6,速览对比!$A$2:$A$63,0)))),"-")) | H18: =IF(H$6="","",IFERROR(IF(ISTEXT(INDEX(速览对比!$AC$2:$AC$63,MATCH(H$6,速览对比!$A$2:$A$63,0))),INDEX(速览对比!$AC$2:$AC$63,MATCH(H$6,速览对比!$A$2:$A$63,0)),IF(INDEX(速览对比!$AC$2:$AC$63,MATCH(H$6,速览对比!$A$2:$A$63,0))=0,"",INDEX(速览对比!$AC$2:$AC$63,MATCH(H$6,速览对比!$A$2:$A$63,0)))),"-"))
B19: =速览对比!$AD$1 -> Memory Bus Width / 显存位宽 | C19: =IF(C$6="","",IFERROR(IF(ISTEXT(INDEX(速览对比!$AD$2:$AD$63,MATCH(C$6,速览对比!$A$2:$A$63,0))),INDEX(速览对比!$AD$2:$AD$63,MATCH(C$6,速览对比!$A$2:$A$63,0)),IF(INDEX(速览对比!$AD$2:$AD$63,MATCH(C$6,速览对比!$A$2:$A$63,0))=0,"",INDEX(速览对比!$AD$2:$AD$63,MATCH(C$6,速览对比!$A$2:$A$63,0)))),"-")) -> 8192-bit | D19: =IF(D$6="","",IFERROR(IF(ISTEXT(INDEX(速览对比!$AD$2:$AD$63,MATCH(D$6,速览对比!$A$2:$A$63,0))),INDEX(速览对比!$AD$2:$AD$63,MATCH(D$6,速览对比!$A$2:$A$63,0)),IF(INDEX(速览对比!$AD$2:$AD$63,MATCH(D$6,速览对比!$A$2:$A$63,0))=0,"",INDEX(速览对比!$AD$2:$AD$63,MATCH(D$6,速览对比!$A$2:$A$63,0)))),"-")) -> 2*4096bit | E19: =IF(E$6="","",IFERROR(IF(ISTEXT(INDEX(速览对比!$AD$2:$AD$63,MATCH(E$6,速览对比!$A$2:$A$63,0))),INDEX(速览对比!$AD$2:$AD$63,MATCH(E$6,速览对比!$A$2:$A$63,0)),IF(INDEX(速览对比!$AD$2:$AD$63,MATCH(E$6,速览对比!$A$2:$A$63,0))=0,"",INDEX(速览对比!$AD$2:$AD$63,MATCH(E$6,速览对比!$A$2:$A$63,0)))),"-")) -> 5120 bit | F19: =IF(F$6="","",IFERROR(IF(ISTEXT(INDEX(速览对比!$AD$2:$AD$63,MATCH(F$6,速览对比!$A$2:$A$63,0))),INDEX(速览对比!$AD$2:$AD$63,MATCH(F$6,速览对比!$A$2:$A$63,0)),IF(INDEX(速览对比!$AD$2:$AD$63,MATCH(F$6,速览对比!$A$2:$A$63,0))=0,"",INDEX(速览对比!$AD$2:$AD$63,MATCH(F$6,速览对比!$A$2:$A$63,0)))),"-")) -> 8192-bit | G19: =IF(G$6="","",IFERROR(IF(ISTEXT(INDEX(速览对比!$AD$2:$AD$63,MATCH(G$6,速览对比!$A$2:$A$63,0))),INDEX(速览对比!$AD$2:$AD$63,MATCH(G$6,速览对比!$A$2:$A$63,0)),IF(INDEX(速览对比!$AD$2:$AD$63,MATCH(G$6,速览对比!$A$2:$A$63,0))=0,"",INDEX(速览对比!$AD$2:$AD$63,MATCH(G$6,速览对比!$A$2:$A$63,0)))),"-")) | H19: =IF(H$6="","",IFERROR(IF(ISTEXT(INDEX(速览对比!$AD$2:$AD$63,MATCH(H$6,速览对比!$A$2:$A$63,0))),INDEX(速览对比!$AD$2:$AD$63,MATCH(H$6,速览对比!$A$2:$A$63,0)),IF(INDEX(速览对比!$AD$2:$AD$63,MATCH(H$6,速览对比!$A$2:$A$63,0))=0,"",INDEX(速览对比!$AD$2:$AD$63,MATCH(H$6,速览对比!$A$2:$A$63,0)))),"-"))
B20: =速览对比!$AE$1 -> Memory Bandwidth / 显存带宽 | C20: =IF(C$6="","",IFERROR(IF(ISTEXT(INDEX(速览对比!$AE$2:$AE$63,MATCH(C$6,速览对比!$A$2:$A$63,0))),INDEX(速览对比!$AE$2:$AE$63,MATCH(C$6,速览对比!$A$2:$A$63,0)),IF(INDEX(速览对比!$AE$2:$AE$63,MATCH(C$6,速览对比!$A$2:$A$63,0))=0,"",INDEX(速览对比!$AE$2:$AE$63,MATCH(C$6,速览对比!$A$2:$A$63,0)))),"-")) -> 8 TB/s | D20: =IF(D$6="","",IFERROR(IF(ISTEXT(INDEX(速览对比!$AE$2:$AE$63,MATCH(D$6,速览对比!$A$2:$A$63,0))),INDEX(速览对比!$AE$2:$AE$63,MATCH(D$6,速览对比!$A$2:$A$63,0)),IF(INDEX(速览对比!$AE$2:$AE$63,MATCH(D$6,速览对比!$A$2:$A$63,0))=0,"",INDEX(速览对比!$AE$2:$AE$63,MATCH(D$6,速览对比!$A$2:$A$63,0)))),"-")) -> 8 TB/s | E20: =IF(E$6="","",IFERROR(IF(ISTEXT(INDEX(速览对比!$AE$2:$AE$63,MATCH(E$6,速览对比!$A$2:$A$63,0))),INDEX(速览对比!$AE$2:$AE$63,MATCH(E$6,速览对比!$A$2:$A$63,0)),IF(INDEX(速览对比!$AE$2:$AE$63,MATCH(E$6,速览对比!$A$2:$A$63,0))=0,"",INDEX(速览对比!$AE$2:$AE$63,MATCH(E$6,速览对比!$A$2:$A$63,0)))),"-")) -> 3.35TB/s | F20: =IF(F$6="","",IFERROR(IF(ISTEXT(INDEX(速览对比!$AE$2:$AE$63,MATCH(F$6,速览对比!$A$2:$A$63,0))),INDEX(速览对比!$AE$2:$AE$63,MATCH(F$6,速览对比!$A$2:$A$63,0)),IF(INDEX(速览对比!$AE$2:$AE$63,MATCH(F$6,速览对比!$A$2:$A$63,0))=0,"",INDEX(速览对比!$AE$2:$AE$63,MATCH(F$6,速览对比!$A$2:$A$63,0)))),"-")) -> 8 TB/s | G20: =IF(G$6="","",IFERROR(IF(ISTEXT(INDEX(速览对比!$AE$2:$AE$63,MATCH(G$6,速览对比!$A$2:$A$63,0))),INDEX(速览对比!$AE$2:$AE$63,MATCH(G$6,速览对比!$A$2:$A$63,0)),IF(INDEX(速览对比!$AE$2:$AE$63,MATCH(G$6,速览对比!$A$2:$A$63,0))=0,"",INDEX(速览对比!$AE$2:$AE$63,MATCH(G$6,速览对比!$A$2:$A$63,0)))),"-")) | H20: =IF(H$6="","",IFERROR(IF(ISTEXT(INDEX(速览对比!$AE$2:$AE$63,MATCH(H$6,速览对比!$A$2:$A$63,0))),INDEX(速览对比!$AE$2:$AE$63,MATCH(H$6,速览对比!$A$2:$A$63,0)),IF(INDEX(速览对比!$AE$2:$AE$63,MATCH(H$6,速览对比!$A$2:$A$63,0))=0,"",INDEX(速览对比!$AE$2:$AE$63,MATCH(H$6,速览对比!$A$2:$A$63,0)))),"-"))
B21: =速览对比!$AF$1 -> VRAM / 显存 | C21: =IF(C$6="","",IFERROR(IF(ISTEXT(INDEX(速览对比!$AF$2:$AF$63,MATCH(C$6,速览对比!$A$2:$A$63,0))),INDEX(速览对比!$AF$2:$AF$63,MATCH(C$6,速览对比!$A$2:$A$63,0)),IF(INDEX(速览对比!$AF$2:$AF$63,MATCH(C$6,速览对比!$A$2:$A$63,0))=0,"",INDEX(速览对比!$AF$2:$AF$63,MATCH(C$6,速览对比!$A$2:$A$63,0)))),"-")) -> 288 GB HBM3e | D21: =IF(D$6="","",IFERROR(IF(ISTEXT(INDEX(速览对比!$AF$2:$AF$63,MATCH(D$6,速览对比!$A$2:$A$63,0))),INDEX(速览对比!$AF$2:$AF$63,MATCH(D$6,速览对比!$A$2:$A$63,0)),IF(INDEX(速览对比!$AF$2:$AF$63,MATCH(D$6,速览对比!$A$2:$A$63,0))=0,"",INDEX(速览对比!$AF$2:$AF$63,MATCH(D$6,速览对比!$A$2:$A$63,0)))),"-")) -> 2*96GB HBM3e=192GB | E21: =IF(E$6="","",IFERROR(IF(ISTEXT(INDEX(速览对比!$AF$2:$AF$63,MATCH(E$6,速览对比!$A$2:$A$63,0))),INDEX(速览对比!$AF$2:$AF$63,MATCH(E$6,速览对比!$A$2:$A$63,0)),IF(INDEX(速览对比!$AF$2:$AF$63,MATCH(E$6,速览对比!$A$2:$A$63,0))=0,"",INDEX(速览对比!$AF$2:$AF$63,MATCH(E$6,速览对比!$A$2:$A$63,0)))),"-")) -> 80GB | F21: =IF(F$6="","",IFERROR(IF(ISTEXT(INDEX(速览对比!$AF$2:$AF$63,MATCH(F$6,速览对比!$A$2:$A$63,0))),INDEX(速览对比!$AF$2:$AF$63,MATCH(F$6,速览对比!$A$2:$A$63,0)),IF(INDEX(速览对比!$AF$2:$AF$63,MATCH(F$6,速览对比!$A$2:$A$63,0))=0,"",INDEX(速览对比!$AF$2:$AF$63,MATCH(F$6,速览对比!$A$2:$A$63,0)))),"-")) -> 288 GB HBM3e（每GPU） | G21: =IF(G$6="","",IFERROR(IF(ISTEXT(INDEX(速览对比!$AF$2:$AF$63,MATCH(G$6,速览对比!$A$2:$A$63,0))),INDEX(速览对比!$AF$2:$AF$63,MATCH(G$6,速览对比!$A$2:$A$63,0)),IF(INDEX(速览对比!$AF$2:$AF$63,MATCH(G$6,速览对比!$A$2:$A$63,0))=0,"",INDEX(速览对比!$AF$2:$AF$63,MATCH(G$6,速览对比!$A$2:$A$63,0)))),"-")) | H21: =IF(H$6="","",IFERROR(IF(ISTEXT(INDEX(速览对比!$AF$2:$AF$63,MATCH(H$6,速览对比!$A$2:$A$63,0))),INDEX(速览对比!$AF$2:$AF$63,MATCH(H$6,速览对比!$A$2:$A$63,0)),IF(INDEX(速览对比!$AF$2:$AF$63,MATCH(H$6,速览对比!$A$2:$A$63,0))=0,"",INDEX(速览对比!$AF$2:$AF$63,MATCH(H$6,速览对比!$A$2:$A$63,0)))),"-"))
B22: =速览对比!$AG$1 -> FP16 Computing (non-Tensor) / 半精性能 non-Tensor | C22: =IF(C$6="","",IFERROR(IF(ISTEXT(INDEX(速览对比!$AG$2:$AG$63,MATCH(C$6,速览对比!$A$2:$A$63,0))),INDEX(速览对比!$AG$2:$AG$63,MATCH(C$6,速览对比!$A$2:$A$63,0)),IF(INDEX(速览对比!$AG$2:$AG$63,MATCH(C$6,速览对比!$A$2:$A$63,0))=0,"",INDEX(速览对比!$AG$2:$AG$63,MATCH(C$6,速览对比!$A$2:$A$63,0)))),"-")) -> ≈150 TFLOPS | D22: =IF(D$6="","",IFERROR(IF(ISTEXT(INDEX(速览对比!$AG$2:$AG$63,MATCH(D$6,速览对比!$A$2:$A$63,0))),INDEX(速览对比!$AG$2:$AG$63,MATCH(D$6,速览对比!$A$2:$A$63,0)),IF(INDEX(速览对比!$AG$2:$AG$63,MATCH(D$6,速览对比!$A$2:$A$63,0))=0,"",INDEX(速览对比!$AG$2:$AG$63,MATCH(D$6,速览对比!$A$2:$A$63,0)))),"-")) -> ≈150 TFLOPS | E22: =IF(E$6="","",IFERROR(IF(ISTEXT(INDEX(速览对比!$AG$2:$AG$63,MATCH(E$6,速览对比!$A$2:$A$63,0))),INDEX(速览对比!$AG$2:$AG$63,MATCH(E$6,速览对比!$A$2:$A$63,0)),IF(INDEX(速览对比!$AG$2:$AG$63,MATCH(E$6,速览对比!$A$2:$A$63,0))=0,"",INDEX(速览对比!$AG$2:$AG$63,MATCH(E$6,速览对比!$A$2:$A$63,0)))),"-")) -> 267.6 TFLOPS | F22: =IF(F$6="","",IFERROR(IF(ISTEXT(INDEX(速览对比!$AG$2:$AG$63,MATCH(F$6,速览对比!$A$2:$A$63,0))),INDEX(速览对比!$AG$2:$AG$63,MATCH(F$6,速览对比!$A$2:$A$63,0)),IF(INDEX(速览对比!$AG$2:$AG$63,MATCH(F$6,速览对比!$A$2:$A$63,0))=0,"",INDEX(速览对比!$AG$2:$AG$63,MATCH(F$6,速览对比!$A$2:$A$63,0)))),"-")) -> ≈166 TFLOPS | G22: =IF(G$6="","",IFERROR(IF(ISTEXT(INDEX(速览对比!$AG$2:$AG$63,MATCH(G$6,速览对比!$A$2:$A$63,0))),INDEX(速览对比!$AG$2:$AG$63,MATCH(G$6,速览对比!$A$2:$A$63,0)),IF(INDEX(速览对比!$AG$2:$AG$63,MATCH(G$6,速览对比!$A$2:$A$63,0))=0,"",INDEX(速览对比!$AG$2:$AG$63,MATCH(G$6,速览对比!$A$2:$A$63,0)))),"-")) | H22: =IF(H$6="","",IFERROR(IF(ISTEXT(INDEX(速览对比!$AG$2:$AG$63,MATCH(H$6,速览对比!$A$2:$A$63,0))),INDEX(速览对比!$AG$2:$AG$63,MATCH(H$6,速览对比!$A$2:$A$63,0)),IF(INDEX(速览对比!$AG$2:$AG$63,MATCH(H$6,速览对比!$A$2:$A$63,0))=0,"",INDEX(速览对比!$AG$2:$AG$63,MATCH(H$6,速览对比!$A$2:$A$63,0)))),"-"))
B23: =速览对比!$AH$1 -> FP16 Tensor Computing/ 半精 Tensor性能 | C23: =IF(C$6="","",IFERROR(IF(ISTEXT(INDEX(速览对比!$AH$2:$AH$63,MATCH(C$6,速览对比!$A$2:$A$63,0))),INDEX(速览对比!$AH$2:$AH$63,MATCH(C$6,速览对比!$A$2:$A$63,0)),IF(INDEX(速览对比!$AH$2:$AH$63,MATCH(C$6,速览对比!$A$2:$A$63,0))=0,"",INDEX(速览对比!$AH$2:$AH$63,MATCH(C$6,速览对比!$A$2:$A$63,0)))),"-")) -> 2,250 | 4,500 TFLOPS² | D23: =IF(D$6="","",IFERROR(IF(ISTEXT(INDEX(速览对比!$AH$2:$AH$63,MATCH(D$6,速览对比!$A$2:$A$63,0))),INDEX(速览对比!$AH$2:$AH$63,MATCH(D$6,速览对比!$A$2:$A$63,0)),IF(INDEX(速览对比!$AH$2:$AH$63,MATCH(D$6,速览对比!$A$2:$A$63,0))=0,"",INDEX(速览对比!$AH$2:$AH$63,MATCH(D$6,速览对比!$A$2:$A$63,0)))),"-")) -> 2,250 | 4,500 TFLOPS² | E23: =IF(E$6="","",IFERROR(IF(ISTEXT(INDEX(速览对比!$AH$2:$AH$63,MATCH(E$6,速览对比!$A$2:$A$63,0))),INDEX(速览对比!$AH$2:$AH$63,MATCH(E$6,速览对比!$A$2:$A$63,0)),IF(INDEX(速览对比!$AH$2:$AH$63,MATCH(E$6,速览对比!$A$2:$A$63,0))=0,"",INDEX(速览对比!$AH$2:$AH$63,MATCH(E$6,速览对比!$A$2:$A$63,0)))),"-")) -> 989 | 1,979 TFLOPS² | F23: =IF(F$6="","",IFERROR(IF(ISTEXT(INDEX(速览对比!$AH$2:$AH$63,MATCH(F$6,速览对比!$A$2:$A$63,0))),INDEX(速览对比!$AH$2:$AH$63,MATCH(F$6,速览对比!$A$2:$A$63,0)),IF(INDEX(速览对比!$AH$2:$AH$63,MATCH(F$6,速览对比!$A$2:$A$63,0))=0,"",INDEX(速览对比!$AH$2:$AH$63,MATCH(F$6,速览对比!$A$2:$A$63,0)))),"-")) -> ≈2,500 | ≈5,000 TFLOPS² | G23: =IF(G$6="","",IFERROR(IF(ISTEXT(INDEX(速览对比!$AH$2:$AH$63,MATCH(G$6,速览对比!$A$2:$A$63,0))),INDEX(速览对比!$AH$2:$AH$63,MATCH(G$6,速览对比!$A$2:$A$63,0)),IF(INDEX(速览对比!$AH$2:$AH$63,MATCH(G$6,速览对比!$A$2:$A$63,0))=0,"",INDEX(速览对比!$AH$2:$AH$63,MATCH(G$6,速览对比!$A$2:$A$63,0)))),"-")) | H23: =IF(H$6="","",IFERROR(IF(ISTEXT(INDEX(速览对比!$AH$2:$AH$63,MATCH(H$6,速览对比!$A$2:$A$63,0))),INDEX(速览对比!$AH$2:$AH$63,MATCH(H$6,速览对比!$A$2:$A$63,0)),IF(INDEX(速览对比!$AH$2:$AH$63,MATCH(H$6,速览对比!$A$2:$A$63,0))=0,"",INDEX(速览对比!$AH$2:$AH$63,MATCH(H$6,速览对比!$A$2:$A$63,0)))),"-"))
B24: =速览对比!$AI$1 -> FP32 Computing (non-Tensor) / 单精性能 non-Tensor | C24: =IF(C$6="","",IFERROR(IF(ISTEXT(INDEX(速览对比!$AI$2:$AI$63,MATCH(C$6,速览对比!$A$2:$A$63,0))),INDEX(速览对比!$AI$2:$AI$63,MATCH(C$6,速览对比!$A$2:$A$63,0)),IF(INDEX(速览对比!$AI$2:$AI$63,MATCH(C$6,速览对比!$A$2:$A$63,0))=0,"",INDEX(速览对比!$AI$2:$AI$63,MATCH(C$6,速览对比!$A$2:$A$63,0)))),"-")) -> 75 TFLOPS | D24: =IF(D$6="","",IFERROR(IF(ISTEXT(INDEX(速览对比!$AI$2:$AI$63,MATCH(D$6,速览对比!$A$2:$A$63,0))),INDEX(速览对比!$AI$2:$AI$63,MATCH(D$6,速览对比!$A$2:$A$63,0)),IF(INDEX(速览对比!$AI$2:$AI$63,MATCH(D$6,速览对比!$A$2:$A$63,0))=0,"",INDEX(速览对比!$AI$2:$AI$63,MATCH(D$6,速览对比!$A$2:$A$63,0)))),"-")) -> 75 TFLOPS | E24: =IF(E$6="","",IFERROR(IF(ISTEXT(INDEX(速览对比!$AI$2:$AI$63,MATCH(E$6,速览对比!$A$2:$A$63,0))),INDEX(速览对比!$AI$2:$AI$63,MATCH(E$6,速览对比!$A$2:$A$63,0)),IF(INDEX(速览对比!$AI$2:$AI$63,MATCH(E$6,速览对比!$A$2:$A$63,0))=0,"",INDEX(速览对比!$AI$2:$AI$63,MATCH(E$6,速览对比!$A$2:$A$63,0)))),"-")) -> 67 TFLOPS | F24: =IF(F$6="","",IFERROR(IF(ISTEXT(INDEX(速览对比!$AI$2:$AI$63,MATCH(F$6,速览对比!$A$2:$A$63,0))),INDEX(速览对比!$AI$2:$AI$63,MATCH(F$6,速览对比!$A$2:$A$63,0)),IF(INDEX(速览对比!$AI$2:$AI$63,MATCH(F$6,速览对比!$A$2:$A$63,0))=0,"",INDEX(速览对比!$AI$2:$AI$63,MATCH(F$6,速览对比!$A$2:$A$63,0)))),"-")) -> ≈83 TFLOPS | G24: =IF(G$6="","",IFERROR(IF(ISTEXT(INDEX(速览对比!$AI$2:$AI$63,MATCH(G$6,速览对比!$A$2:$A$63,0))),INDEX(速览对比!$AI$2:$AI$63,MATCH(G$6,速览对比!$A$2:$A$63,0)),IF(INDEX(速览对比!$AI$2:$AI$63,MATCH(G$6,速览对比!$A$2:$A$63,0))=0,"",INDEX(速览对比!$AI$2:$AI$63,MATCH(G$6,速览对比!$A$2:$A$63,0)))),"-")) | H24: =IF(H$6="","",IFERROR(IF(ISTEXT(INDEX(速览对比!$AI$2:$AI$63,MATCH(H$6,速览对比!$A$2:$A$63,0))),INDEX(速览对比!$AI$2:$AI$63,MATCH(H$6,速览对比!$A$2:$A$63,0)),IF(INDEX(速览对比!$AI$2:$AI$63,MATCH(H$6,速览对比!$A$2:$A$63,0))=0,"",INDEX(速览对比!$AI$2:$AI$63,MATCH(H$6,速览对比!$A$2:$A$63,0)))),"-"))
B25: =速览对比!$AJ$1 -> TF32 Tensor Computing / TF32 Tensor性能 | C25: =IF(C$6="","",IFERROR(IF(ISTEXT(INDEX(速览对比!$AJ$2:$AJ$63,MATCH(C$6,速览对比!$A$2:$A$63,0))),INDEX(速览对比!$AJ$2:$AJ$63,MATCH(C$6,速览对比!$A$2:$A$63,0)),IF(INDEX(速览对比!$AJ$2:$AJ$63,MATCH(C$6,速览对比!$A$2:$A$63,0))=0,"",INDEX(速览对比!$AJ$2:$AJ$63,MATCH(C$6,速览对比!$A$2:$A$63,0)))),"-")) -> 1,125 | 2,250 TFLOPS² | D25: =IF(D$6="","",IFERROR(IF(ISTEXT(INDEX(速览对比!$AJ$2:$AJ$63,MATCH(D$6,速览对比!$A$2:$A$63,0))),INDEX(速览对比!$AJ$2:$AJ$63,MATCH(D$6,速览对比!$A$2:$A$63,0)),IF(INDEX(速览对比!$AJ$2:$AJ$63,MATCH(D$6,速览对比!$A$2:$A$63,0))=0,"",INDEX(速览对比!$AJ$2:$AJ$63,MATCH(D$6,速览对比!$A$2:$A$63,0)))),"-")) -> 1,125 | 2,250 TFLOPS² | E25: =IF(E$6="","",IFERROR(IF(ISTEXT(INDEX(速览对比!$AJ$2:$AJ$63,MATCH(E$6,速览对比!$A$2:$A$63,0))),INDEX(速览对比!$AJ$2:$AJ$63,MATCH(E$6,速览对比!$A$2:$A$63,0)),IF(INDEX(速览对比!$AJ$2:$AJ$63,MATCH(E$6,速览对比!$A$2:$A$63,0))=0,"",INDEX(速览对比!$AJ$2:$AJ$63,MATCH(E$6,速览对比!$A$2:$A$63,0)))),"-")) -> 494 | 989 TFLOPS² | F25: =IF(F$6="","",IFERROR(IF(ISTEXT(INDEX(速览对比!$AJ$2:$AJ$63,MATCH(F$6,速览对比!$A$2:$A$63,0))),INDEX(速览对比!$AJ$2:$AJ$63,MATCH(F$6,速览对比!$A$2:$A$63,0)),IF(INDEX(速览对比!$AJ$2:$AJ$63,MATCH(F$6,速览对比!$A$2:$A$63,0))=0,"",INDEX(速览对比!$AJ$2:$AJ$63,MATCH(F$6,速览对比!$A$2:$A$63,0)))),"-")) -> ≈1,250 | ≈2,500 TFLOPS² | G25: =IF(G$6="","",IFERROR(IF(ISTEXT(INDEX(速览对比!$AJ$2:$AJ$63,MATCH(G$6,速览对比!$A$2:$A$63,0))),INDEX(速览对比!$AJ$2:$AJ$63,MATCH(G$6,速览对比!$A$2:$A$63,0)),IF(INDEX(速览对比!$AJ$2:$AJ$63,MATCH(G$6,速览对比!$A$2:$A$63,0))=0,"",INDEX(速览对比!$AJ$2:$AJ$63,MATCH(G$6,速览对比!$A$2:$A$63,0)))),"-")) | H25: =IF(H$6="","",IFERROR(IF(ISTEXT(INDEX(速览对比!$AJ$2:$AJ$63,MATCH(H$6,速览对比!$A$2:$A$63,0))),INDEX(速览对比!$AJ$2:$AJ$63,MATCH(H$6,速览对比!$A$2:$A$63,0)),IF(INDEX(速览对比!$AJ$2:$AJ$63,MATCH(H$6,速览对比!$A$2:$A$63,0))=0,"",INDEX(速览对比!$AJ$2:$AJ$63,MATCH(H$6,速览对比!$A$2:$A$63,0)))),"-"))
B26: =速览对比!$AK$1 -> FP64 Computing (non-Tensor) / 双精性能 non-Tensor | C26: =IF(C$6="","",IFERROR(IF(ISTEXT(INDEX(速览对比!$AK$2:$AK$63,MATCH(C$6,速览对比!$A$2:$A$63,0))),INDEX(速览对比!$AK$2:$AK$63,MATCH(C$6,速览对比!$A$2:$A$63,0)),IF(INDEX(速览对比!$AK$2:$AK$63,MATCH(C$6,速览对比!$A$2:$A$63,0))=0,"",INDEX(速览对比!$AK$2:$AK$63,MATCH(C$6,速览对比!$A$2:$A$63,0)))),"-")) -> ≈1.25 TFLOPS | D26: =IF(D$6="","",IFERROR(IF(ISTEXT(INDEX(速览对比!$AK$2:$AK$63,MATCH(D$6,速览对比!$A$2:$A$63,0))),INDEX(速览对比!$AK$2:$AK$63,MATCH(D$6,速览对比!$A$2:$A$63,0)),IF(INDEX(速览对比!$AK$2:$AK$63,MATCH(D$6,速览对比!$A$2:$A$63,0))=0,"",INDEX(速览对比!$AK$2:$AK$63,MATCH(D$6,速览对比!$A$2:$A$63,0)))),"-")) -> 37 TFLOPS | E26: =IF(E$6="","",IFERROR(IF(ISTEXT(INDEX(速览对比!$AK$2:$AK$63,MATCH(E$6,速览对比!$A$2:$A$63,0))),INDEX(速览对比!$AK$2:$AK$63,MATCH(E$6,速览对比!$A$2:$A$63,0)),IF(INDEX(速览对比!$AK$2:$AK$63,MATCH(E$6,速览对比!$A$2:$A$63,0))=0,"",INDEX(速览对比!$AK$2:$AK$63,MATCH(E$6,速览对比!$A$2:$A$63,0)))),"-")) -> 34 TFLOPS | F26: =IF(F$6="","",IFERROR(IF(ISTEXT(INDEX(速览对比!$AK$2:$AK$63,MATCH(F$6,速览对比!$A$2:$A$63,0))),INDEX(速览对比!$AK$2:$AK$63,MATCH(F$6,速览对比!$A$2:$A$63,0)),IF(INDEX(速览对比!$AK$2:$AK$63,MATCH(F$6,速览对比!$A$2:$A$63,0))=0,"",INDEX(速览对比!$AK$2:$AK$63,MATCH(F$6,速览对比!$A$2:$A$63,0)))),"-")) -> ≈1.4 TFLOPS | G26: =IF(G$6="","",IFERROR(IF(ISTEXT(INDEX(速览对比!$AK$2:$AK$63,MATCH(G$6,速览对比!$A$2:$A$63,0))),INDEX(速览对比!$AK$2:$AK$63,MATCH(G$6,速览对比!$A$2:$A$63,0)),IF(INDEX(速览对比!$AK$2:$AK$63,MATCH(G$6,速览对比!$A$2:$A$63,0))=0,"",INDEX(速览对比!$AK$2:$AK$63,MATCH(G$6,速览对比!$A$2:$A$63,0)))),"-")) | H26: =IF(H$6="","",IFERROR(IF(ISTEXT(INDEX(速览对比!$AK$2:$AK$63,MATCH(H$6,速览对比!$A$2:$A$63,0))),INDEX(速览对比!$AK$2:$AK$63,MATCH(H$6,速览对比!$A$2:$A$63,0)),IF(INDEX(速览对比!$AK$2:$AK$63,MATCH(H$6,速览对比!$A$2:$A$63,0))=0,"",INDEX(速览对比!$AK$2:$AK$63,MATCH(H$6,速览对比!$A$2:$A$63,0)))),"-"))
